Workbook

Sheet 0_Cover
B2: PERHITUNGAN MANUAL K-MEANS++
B3: Pengembangan Model Konseptual Intelijen Spasial Berbasis Klasterisasi K-Means++ dan Analisis Spatio-Temporal
B4: untuk Pemodelan Dinamis Potensi Wisata di Kabupaten Magelang
B6: No | C6: Sheet | E6: Isi / Konten | H6: Metode Utama
B7: 1 | C7: 1_Dataset | E7: Dataset spatio-temporal 15 destinasi wisata Magelang dengan 10 atribut | H7: Data Input (Biru)
B8: 2 | C8: 2_Normalisasi | E8: Normalisasi Min-Max semua fitur numerik ke rentang [0,1] | H8: Formula Min-Max
B9: 3 | C9: 3_KMeans++_Init | E9: Inisialisasi centroid K-Means++ berbasis probabilitas D² | H9: Langkah 1-4
B10: 4 | C10: 4_Iterasi_KMeans++ | E10: Penugasan klaster & update centroid (Iterasi 1) | H10: Jarak Euclidean
B11: 5 | C11: 5_Konvergensi | E11: Tracking pergeseran centroid & deteksi konvergensi | H11: Analisis Δ Centroid
B12: 6 | C12: 6_Hasil_Klaster | E12: Hasil final klasterisasi + skor potensi per destinasi | H12: Output Final
B13: 7 | C13: 7_Evaluasi_Metrik | E13: SC, DBI, CHI – tiga metrik evaluasi kualitas klaster | H13: Evaluasi Model
B14: 8 | C14: 8_Spatio_Temporal | E14: Analisis spasial per klaster & proyeksi temporal 3 tahun | H14: Proyeksi Kunjungan
B16: Kode Warna: Biru = Input hardcoded | Hitam = Formula kalkulasi | Kuning = Nilai kritis | Hijau = Hasil/output

Sheet 1_Dataset
A1: DATASET SPATIO-TEMPORAL DESTINASI WISATA – KABUPATEN MAGELANG
A2: Penelitian: Pengembangan Model Konseptual Intelijen Spasial Berbasis K-Means++
A3: ID | B3: Nama Destinasi | C3: Longitude (X) | D3: Latitude (Y) | E3: Jml Kunjungan/Tahun | F3: Rating (1-5) | G3: Aksesibilitas (1-5) | H3: Fasilitas (1-5) | I3: Potensi Alam (1-5) | J3: Potensi Budaya (1-5) | K3: Pendapatan (Juta Rp) | L3: Trend YoY (%) | M3: Zona Temporal
A4: 1 | B4: Candi Borobudur | C4: 110.2037 | D4: -7.6079 | E4: 1250000 | F4: 4.9 | G4: 5 | H4: 5 | I4: 4 | J4: 5 | K4: 18500 | L4: 0.123 | M4: Peak Season
A5: 2 | B5: Punthuk Setumbu | C5: 110.1952 | D5: -7.6025 | E5: 185000 | F5: 4.7 | G5: 3 | H5: 3 | I5: 5 | J5: 4 | K5: 2800 | L5: 0.185 | M5: Peak Season
A6: 3 | B6: Candi Pawon | C6: 110.2105 | D6: -7.6112 | E6: 95000 | F6: 4.2 | G6: 4 | H6: 3 | I6: 3 | J6: 5 | K6: 850 | L6: 0.082 | M6: Mid Season
A7: 4 | B7: Candi Mendut | C7: 110.2278 | D7: -7.5996 | E7: 125000 | F7: 4.3 | G7: 4 | H7: 4 | I7: 3 | J7: 5 | K7: 1200 | L7: 0.095 | M7: Mid Season
A8: 5 | B8: Ketep Pass | C8: 110.2564 | D8: -7.5847 | E8: 210000 | F8: 4.5 | G8: 3 | H8: 4 | I8: 5 | J8: 3 | K8: 3100 | L8: 0.157 | M8: Peak Season
A9: 6 | B9: Kopeng | C9: 110.4012 | D9: -7.3985 | E9: 98000 | F9: 3.8 | G9: 3 | H9: 3 | I9: 4 | J9: 2 | K9: 780 | L9: 0.053 | M9: Low Season
A10: 7 | B10: Air Terjun Kedung Kayang | C10: 110.2689 | D10: -7.5712 | E10: 42000 | F10: 4.4 | G10: 2 | H10: 2 | I10: 5 | J10: 2 | K10: 320 | L10: 0.221 | M10: Low Season
A11: 8 | B11: Telaga Bleder | C11: 110.3215 | D11: -7.4823 | E11: 35000 | F11: 3.9 | G11: 2 | H11: 2 | I11: 4 | J11: 2 | K11: 280 | L11: 0.118 | M11: Low Season
A12: 9 | B12: Bukit Rhema (Gereja Ayam) | C12: 110.2021 | D12: -7.6038 | E12: 165000 | F12: 4.6 | G12: 3 | H12: 3 | I12: 4 | J12: 4 | K12: 2100 | L12: 0.352 | M12: Peak Season
A13: 10 | B13: Sawah Sukomakmur | C13: 110.2334 | D13: -7.5698 | E13: 28000 | F13: 4.1 | G13: 2 | H13: 2 | I13: 5 | J13: 3 | K13: 210 | L13: 0.284 | M13: Low Season
A14: 11 | B14: Museum Karmawibhangga | C14: 110.2039 | D14: -7.6082 | E14: 87000 | F14: 4 | G14: 5 | H14: 4 | I14: 2 | J14: 5 | K14: 650 | L14: 0.061 | M14: Mid Season
A15: 12 | B15: Taman Kyai Langgeng | C15: 110.2176 | D15: -7.4721 | E15: 145000 | F15: 3.7 | G15: 4 | H15: 4 | I15: 3 | J15: 3 | K15: 1850 | L15: 0.042 | M15: Mid Season
... A18: 15 | B18: Puthuk Mongkrong | C18: 110.1998 | D18: -7.5987 | E18: 45000 | F18: 4.3 | G18: 2 | H18: 2 | I18: 5 | J18: 4 | K18: 380 | L18: 0.412 | M18: Low Season

Sheet 2_Normalisasi
A1: PRA-PEMROSESAN: NORMALISASI MIN-MAX DATA SPATIO-TEMPORAL
A2: Formula: X_norm = (X - X_min) / (X_max - X_min) | Rentang hasil: [0, 1]
A3: Statistik | C3: Longitude | D3: Latitude | E3: Kunjungan | F3: Rating | G3: Akses | H3: Fasilitas | I3: P.Alam | J3: P.Budaya | K3: Pendapatan | L3: Trend
A4: Min | C4: =MIN('1_Dataset'!C4:C18) -> 110.1952 | D4: =MIN('1_Dataset'!D4:D18) -> -7.6112 | E4: =MIN('1_Dataset'!E4:E18) -> 28000 | F4: =MIN('1_Dataset'!F4:F18) -> 3.7 | G4: =MIN('1_Dataset'!G4:G18) -> 2 | H4: =MIN('1_Dataset'!H4:H18) -> 2 | I4: =MIN('1_Dataset'!I4:I18) -> 2 | J4: =MIN('1_Dataset'!J4:J18) -> 2 | ... L4: =MIN('1_Dataset'!L4:L18) -> 0.042
A5: Max | C5: =MAX('1_Dataset'!C4:C18) -> 110.4125 | D5: =MAX('1_Dataset'!D4:D18) -> -7.3654 | E5: =MAX('1_Dataset'!E4:E18) -> 1250000 | F5: =MAX('1_Dataset'!F4:F18) -> 4.9 | G5: =MAX('1_Dataset'!G4:G18) -> 5 | H5: =MAX('1_Dataset'!H4:H18) -> 5 | I5: =MAX('1_Dataset'!I4:I18) -> 5 | J5: =MAX('1_Dataset'!J4:J18) -> 5 | ... L5: =MAX('1_Dataset'!L4:L18) -> 0.412
A6: Range | C6: =C5-C4 -> 0.2173 | D6: =D5-D4 -> 0.2458 | E6: =E5-E4 -> 1222000 | F6: =F5-F4 -> 1.2 | G6: =G5-G4 -> 3 | H6: =H5-H4 -> 3 | I6: =I5-I4 -> 3 | J6: =J5-J4 -> 3 | ... L6: =L5-L4 -> 0.37
A7: ID | B7: Nama Destinasi | C7: Lon_norm | D7: Lat_norm | E7: Visit_norm | F7: Rating_norm | G7: Akses_norm | H7: Fas_norm | I7: Alam_norm | J7: Budaya_norm | K7: Pend_norm | L7: Trend_norm
A8: ='1_Dataset'!A4 -> 1 | B8: ='1_Dataset'!B4 -> Candi Borobudur | C8: =IF(C$6=0,0,('1_Dataset'!C4-C$4)/C$6) -> 0.039116429 | D8: =IF(D$6=0,0,('1_Dataset'!D4-D$4)/D$6) -> 0.013425549 | E8: =IF(E$6=0,0,('1_Dataset'!E4-E$4)/E$6) -> 1 | F8: =IF(F$6=0,0,('1_Dataset'!F4-F$4)/F$6) -> 1 | G8: =IF(G$6=0,0,('1_Dataset'!G4-G$4)/G$6) -> 1 | H8: =IF(H$6=0,0,('1_Dataset'!H4-H$4)/H$6) -> 1 | I8: =IF(I$6=0,0,('1_Dataset'!I4-I$4)/I$6) -> 0.66666667 | J8: =IF(J$6=0,0,('1_Dataset'!J4-J$4)/J$6) -> 1 | ... L8: =IF(L$6=0,0,('1_Dataset'!L4-L$4)/L$6) -> 0.21891892
A9: ='1_Dataset'!A5 -> 2 | B9: ='1_Dataset'!B5 -> Punthuk Setumbu | C9: =IF(C$6=0,0,('1_Dataset'!C5-C$4)/C$6) -> 0 | D9: =IF(D$6=0,0,('1_Dataset'!D5-D$4)/D$6) -> 0.03539463 | E9: =IF(E$6=0,0,('1_Dataset'!E5-E$4)/E$6) -> 0.12847791 | F9: =IF(F$6=0,0,('1_Dataset'!F5-F$4)/F$6) -> 0.83333333 | G9: =IF(G$6=0,0,('1_Dataset'!G5-G$4)/G$6) -> 0.33333333 | H9: =IF(H$6=0,0,('1_Dataset'!H5-H$4)/H$6) -> 0.33333333 | I9: =IF(I$6=0,0,('1_Dataset'!I5-I$4)/I$6) -> 1 | J9: =IF(J$6=0,0,('1_Dataset'!J5-J$4)/J$6) -> 0.66666667 | ... L9: =IF(L$6=0,0,('1_Dataset'!L5-L$4)/L$6) -> 0.38648649
A10: ='1_Dataset'!A6 -> 3 | B10: ='1_Dataset'!B6 -> Candi Pawon | C10: =IF(C$6=0,0,('1_Dataset'!C6-C$4)/C$6) -> 0.070409572 | D10: =IF(D$6=0,0,('1_Dataset'!D6-D$4)/D$6) -> 0 | E10: =IF(E$6=0,0,('1_Dataset'!E6-E$4)/E$6) -> 0.054828151 | F10: =IF(F$6=0,0,('1_Dataset'!F6-F$4)/F$6) -> 0.41666667 | G10: =IF(G$6=0,0,('1_Dataset'!G6-G$4)/G$6) -> 0.66666667 | H10: =IF(H$6=0,0,('1_Dataset'!H6-H$4)/H$6) -> 0.33333333 | I10: =IF(I$6=0,0,('1_Dataset'!I6-I$4)/I$6) -> 0.33333333 | J10: =IF(J$6=0,0,('1_Dataset'!J6-J$4)/J$6) -> 1 | ... L10: =IF(L$6=0,0,('1_Dataset'!L6-L$4)/L$6) -> 0.10810811
A11: ='1_Dataset'!A7 -> 4 | B11: ='1_Dataset'!B7 -> Candi Mendut | C11: =IF(C$6=0,0,('1_Dataset'!C7-C$4)/C$6) -> 0.15002301 | D11: =IF(D$6=0,0,('1_Dataset'!D7-D$4)/D$6) -> 0.04719284 | E11: =IF(E$6=0,0,('1_Dataset'!E7-E$4)/E$6) -> 0.079378069 | F11: =IF(F$6=0,0,('1_Dataset'!F7-F$4)/F$6) -> 0.5 | G11: =IF(G$6=0,0,('1_Dataset'!G7-G$4)/G$6) -> 0.66666667 | H11: =IF(H$6=0,0,('1_Dataset'!H7-H$4)/H$6) -> 0.66666667 | I11: =IF(I$6=0,0,('1_Dataset'!I7-I$4)/I$6) -> 0.33333333 | J11: =IF(J$6=0,0,('1_Dataset'!J7-J$4)/J$6) -> 1 | ... L11: =IF(L$6=0,0,('1_Dataset'!L7-L$4)/L$6) -> 0.14324324
A12: ='1_Dataset'!A8 -> 5 | B12: ='1_Dataset'!B8 -> Ketep Pass | C12: =IF(C$6=0,0,('1_Dataset'!C8-C$4)/C$6) -> 0.28163829 | D12: =IF(D$6=0,0,('1_Dataset'!D8-D$4)/D$6) -> 0.10781123 | E12: =IF(E$6=0,0,('1_Dataset'!E8-E$4)/E$6) -> 0.14893617 | F12: =IF(F$6=0,0,('1_Dataset'!F8-F$4)/F$6) -> 0.66666667 | G12: =IF(G$6=0,0,('1_Dataset'!G8-G$4)/G$6) -> 0.33333333 | H12: =IF(H$6=0,0,('1_Dataset'!H8-H$4)/H$6) -> 0.66666667 | I12: =IF(I$6=0,0,('1_Dataset'!I8-I$4)/I$6) -> 1 | J12: =IF(J$6=0,0,('1_Dataset'!J8-J$4)/J$6) -> 0.33333333 | ... L12: =IF(L$6=0,0,('1_Dataset'!L8-L$4)/L$6) -> 0.31081081
A13: ='1_Dataset'!A9 -> 6 | B13: ='1_Dataset'!B9 -> Kopeng | C13: =IF(C$6=0,0,('1_Dataset'!C9-C$4)/C$6) -> 0.94799816 | D13: =IF(D$6=0,0,('1_Dataset'!D9-D$4)/D$6) -> 0.86533767 | E13: =IF(E$6=0,0,('1_Dataset'!E9-E$4)/E$6) -> 0.057283142 | F13: =IF(F$6=0,0,('1_Dataset'!F9-F$4)/F$6) -> 0.083333333 | G13: =IF(G$6=0,0,('1_Dataset'!G9-G$4)/G$6) -> 0.33333333 | H13: =IF(H$6=0,0,('1_Dataset'!H9-H$4)/H$6) -> 0.33333333 | I13: =IF(I$6=0,0,('1_Dataset'!I9-I$4)/I$6) -> 0.66666667 | J13: =IF(J$6=0,0,('1_Dataset'!J9-J$4)/J$6) -> 0 | ... L13: =IF(L$6=0,0,('1_Dataset'!L9-L$4)/L$6) -> 0.02972973
A14: ='1_Dataset'!A10 -> 7 | B14: ='1_Dataset'!B10 -> Air Terjun Kedung Kayang | C14: =IF(C$6=0,0,('1_Dataset'!C10-C$4)/C$6) -> 0.33916245 | D14: =IF(D$6=0,0,('1_Dataset'!D10-D$4)/D$6) -> 0.16273393 | E14: =IF(E$6=0,0,('1_Dataset'!E10-E$4)/E$6) -> 0.011456628 | F14: =IF(F$6=0,0,('1_Dataset'!F10-F$4)/F$6) -> 0.58333333 | G14: =IF(G$6=0,0,('1_Dataset'!G10-G$4)/G$6) -> 0 | H14: =IF(H$6=0,0,('1_Dataset'!H10-H$4)/H$6) -> 0 | I14: =IF(I$6=0,0,('1_Dataset'!I10-I$4)/I$6) -> 1 | J14: =IF(J$6=0,0,('1_Dataset'!J10-J$4)/J$6) -> 0 | ... L14: =IF(L$6=0,0,('1_Dataset'!L10-L$4)/L$6) -> 0.48378378
A15: ='1_Dataset'!A11 -> 8 | B15: ='1_Dataset'!B11 -> Telaga Bleder | C15: =IF(C$6=0,0,('1_Dataset'!C11-C$4)/C$6) -> 0.58122411 | D15: =IF(D$6=0,0,('1_Dataset'!D11-D$4)/D$6) -> 0.52441009 | E15: =IF(E$6=0,0,('1_Dataset'!E11-E$4)/E$6) -> 0.0057283142 | F15: =IF(F$6=0,0,('1_Dataset'!F11-F$4)/F$6) -> 0.16666667 | G15: =IF(G$6=0,0,('1_Dataset'!G11-G$4)/G$6) -> 0 | H15: =IF(H$6=0,0,('1_Dataset'!H11-H$4)/H$6) -> 0 | I15: =IF(I$6=0,0,('1_Dataset'!I11-I$4)/I$6) -> 0.66666667 | J15: =IF(J$6=0,0,('1_Dataset'!J11-J$4)/J$6) -> 0 | ... L15: =IF(L$6=0,0,('1_Dataset'!L11-L$4)/L$6) -> 0.20540541
A16: ='1_Dataset'!A12 -> 9 | B16: ='1_Dataset'!B12 -> Bukit Rhema (Gereja Ayam) | C16: =IF(C$6=0,0,('1_Dataset'!C12-C$4)/C$6) -> 0.031753336 | D16: =IF(D$6=0,0,('1_Dataset'!D12-D$4)/D$6) -> 0.030105777 | E16: =IF(E$6=0,0,('1_Dataset'!E12-E$4)/E$6) -> 0.11211129 | F16: =IF(F$6=0,0,('1_Dataset'!F12-F$4)/F$6) -> 0.75 | G16: =IF(G$6=0,0,('1_Dataset'!G12-G$4)/G$6) -> 0.33333333 | H16: =IF(H$6=0,0,('1_Dataset'!H12-H$4)/H$6) -> 0.33333333 | I16: =IF(I$6=0,0,('1_Dataset'!I12-I$4)/I$6) -> 0.66666667 | J16: =IF(J$6=0,0,('1_Dataset'!J12-J$4)/J$6) -> 0.66666667 | ... L16: =IF(L$6=0,0,('1_Dataset'!L12-L$4)/L$6) -> 0.83783784
A17: ='1_Dataset'!A13 -> 10 | B17: ='1_Dataset'!B13 -> Sawah Sukomakmur | C17: =IF(C$6=0,0,('1_Dataset'!C13-C$4)/C$6) -> 0.17579383 | D17: =IF(D$6=0,0,('1_Dataset'!D13-D$4)/D$6) -> 0.16842962 | E17: =IF(E$6=0,0,('1_Dataset'!E13-E$4)/E$6) -> 0 | F17: =IF(F$6=0,0,('1_Dataset'!F13-F$4)/F$6) -> 0.33333333 | G17: =IF(G$6=0,0,('1_Dataset'!G13-G$4)/G$6) -> 0 | H17: =IF(H$6=0,0,('1_Dataset'!H13-H$4)/H$6) -> 0 | I17: =IF(I$6=0,0,('1_Dataset'!I13-I$4)/I$6) -> 1 | J17: =IF(J$6=0,0,('1_Dataset'!J13-J$4)/J$6) -> 0.33333333 | ... L17: =IF(L$6=0,0,('1_Dataset'!L13-L$4)/L$6) -> 0.65405405
A18: ='1_Dataset'!A14 -> 11 | B18: ='1_Dataset'!B14 -> Museum Karmawibhangga | C18: =IF(C$6=0,0,('1_Dataset'!C14-C$4)/C$6) -> 0.040036815 | D18: =IF(D$6=0,0,('1_Dataset'!D14-D$4)/D$6) -> 0.012205045 | E18: =IF(E$6=0,0,('1_Dataset'!E14-E$4)/E$6) -> 0.048281506 | F18: =IF(F$6=0,0,('1_Dataset'!F14-F$4)/F$6) -> 0.25 | G18: =IF(G$6=0,0,('1_Dataset'!G14-G$4)/G$6) -> 1 | H18: =IF(H$6=0,0,('1_Dataset'!H14-H$4)/H$6) -> 0.66666667 | I18: =IF(I$6=0,0,('1_Dataset'!I14-I$4)/I$6) -> 0 | J18: =IF(J$6=0,0,('1_Dataset'!J14-J$4)/J$6) -> 1 | ... L18: =IF(L$6=0,0,('1_Dataset'!L14-L$4)/L$6) -> 0.051351351
A19: ='1_Dataset'!A15 -> 12 | B19: ='1_Dataset'!B15 -> Taman Kyai Langgeng | C19: =IF(C$6=0,0,('1_Dataset'!C15-C$4)/C$6) -> 0.10308329 | D19: =IF(D$6=0,0,('1_Dataset'!D15-D$4)/D$6) -> 0.56590724 | E19: =IF(E$6=0,0,('1_Dataset'!E15-E$4)/E$6) -> 0.095744681 | F19: =IF(F$6=0,0,('1_Dataset'!F15-F$4)/F$6) -> 0 | G19: =IF(G$6=0,0,('1_Dataset'!G15-G$4)/G$6) -> 0.66666667 | H19: =IF(H$6=0,0,('1_Dataset'!H15-H$4)/H$6) -> 0.66666667 | I19: =IF(I$6=0,0,('1_Dataset'!I15-I$4)/I$6) -> 0.33333333 | J19: =IF(J$6=0,0,('1_Dataset'!J15-J$4)/J$6) -> 0.33333333 | ... L19: =IF(L$6=0,0,('1_Dataset'!L15-L$4)/L$6) -> 0
... A22: ='1_Dataset'!A18 -> 15 | B22: ='1_Dataset'!B18 -> Puthuk Mongkrong | C22: =IF(C$6=0,0,('1_Dataset'!C18-C$4)/C$6) -> 0.021168891 | D22: =IF(D$6=0,0,('1_Dataset'!D18-D$4)/D$6) -> 0.050854353 | E22: =IF(E$6=0,0,('1_Dataset'!E18-E$4)/E$6) -> 0.01391162 | F22: =IF(F$6=0,0,('1_Dataset'!F18-F$4)/F$6) -> 0.5 | G22: =IF(G$6=0,0,('1_Dataset'!G18-G$4)/G$6) -> 0 | H22: =IF(H$6=0,0,('1_Dataset'!H18-H$4)/H$6) -> 0 | I22: =IF(I$6=0,0,('1_Dataset'!I18-I$4)/I$6) -> 1 | J22: =IF(J$6=0,0,('1_Dataset'!J18-J$4)/J$6) -> 0.66666667 | ... L22: =IF(L$6=0,0,('1_Dataset'!L18-L$4)/L$6) -> 1

Sheet 3_KMeans++_Init
A1: K-MEANS++ INISIALISASI CENTROID – PROSEDUR PEMILIHAN BERBASIS PROBABILITAS
A2: K-Means++ memilih centroid awal dengan probabilitas proporsional terhadap D²(x) – jarak kuadrat minimum ke centroid yang sudah dipilih. Hal ini menjamin konvergensi lebih cepat dan menghindari inisialisasi buruk dibanding K-Means biasa.
A4: PARAMETER K-MEANS++
A5: K (jumlah klaster) | C5: 3
A6: Fitur digunakan | C6: 10
A7: Metode jarak | C7: Euclidean
A8: Seed centroid-1 | C8: ID=1 (Borobudur – manual)
A10: LANGKAH 1: Centroid C1 = Titik pertama (ID 1 – Candi Borobudur)
A11: Centroid C1 | B11: Lon_n | C11: Lat_n | D11: Visit_n | E11: Rating_n | F11: Akses_n | G11: Fas_n | H11: Alam_n | I11: Budaya_n | J11: Pend_n | K11: Trend_n
A12: C1 Values | B12: ='2_Normalisasi'!C8 -> 0.039116429 | C12: ='2_Normalisasi'!D8 -> 0.013425549 | D12: ='2_Normalisasi'!E8 -> 1 | E12: ='2_Normalisasi'!F8 -> 1 | F12: ='2_Normalisasi'!G8 -> 1 | G12: ='2_Normalisasi'!H8 -> 1 | H12: ='2_Normalisasi'!I8 -> 0.66666667 | I12: ='2_Normalisasi'!J8 -> 1 | ... K12: ='2_Normalisasi'!L8 -> 0.21891892
A14: LANGKAH 2: Hitung D²(x,C1) = Σ(xi – C1i)² untuk semua titik
A15: ID | B15: Nama | C15: Lon_n | D15: Lat_n | E15: Visit_n | F15: Rating_n | G15: Akses_n | H15: Fas_n | I15: Alam_n | J15: Budaya_n | K15: Pend_n | L15: Trend_n | M15: D²(x,C1) | N15: P(x) Kumulatif
A16: ='2_Normalisasi'!A8 -> 1 | B16: ='2_Normalisasi'!B8 -> Candi Borobudur | C16: ='2_Normalisasi'!C8 -> 0.039116429 | D16: ='2_Normalisasi'!D8 -> 0.013425549 | E16: ='2_Normalisasi'!E8 -> 1 | F16: ='2_Normalisasi'!F8 -> 1 | G16: ='2_Normalisasi'!G8 -> 1 | H16: ='2_Normalisasi'!H8 -> 1 | ... L16: ='2_Normalisasi'!L8 -> 0.21891892 | M16: =(C16-B$12)^2+(D16-C$12)^2+(E16-D$12)^2+(F16-E$12)^2+(G16-F$12)^2+(H16-G$12)^2+(I16-H$12)^2+(J16-I$12)^2+(K16-J$12)^2+(L16-K$12)^2 -> 0 | N16: =M16/SUM(M$16:M$30) -> 0
A17: ='2_Normalisasi'!A9 -> 2 | B17: ='2_Normalisasi'!B9 -> Punthuk Setumbu | C17: ='2_Normalisasi'!C9 -> 0 | D17: ='2_Normalisasi'!D9 -> 0.03539463 | E17: ='2_Normalisasi'!E9 -> 0.12847791 | F17: ='2_Normalisasi'!F9 -> 0.83333333 | G17: ='2_Normalisasi'!G9 -> 0.33333333 | H17: ='2_Normalisasi'!H9 -> 0.33333333 | ... L17: ='2_Normalisasi'!L9 -> 0.38648649 | M17: =(C17-B$12)^2+(D17-C$12)^2+(E17-D$12)^2+(F17-E$12)^2+(G17-F$12)^2+(H17-G$12)^2+(I17-H$12)^2+(J17-I$12)^2+(K17-J$12)^2+(L17-K$12)^2 -> 2.6653691 | N17: =N16+M17/SUM(M$16:M$30) -> 0.042644603
A18: ='2_Normalisasi'!A10 -> 3 | B18: ='2_Normalisasi'!B10 -> Candi Pawon | C18: ='2_Normalisasi'!C10 -> 0.070409572 | D18: ='2_Normalisasi'!D10 -> 0 | E18: ='2_Normalisasi'!E10 -> 0.054828151 | F18: ='2_Normalisasi'!F10 -> 0.41666667 | G18: ='2_Normalisasi'!G10 -> 0.66666667 | H18: ='2_Normalisasi'!H10 -> 0.33333333 | ... L18: ='2_Normalisasi'!L10 -> 0.10810811 | M18: =(C18-B$12)^2+(D18-C$12)^2+(E18-D$12)^2+(F18-E$12)^2+(G18-F$12)^2+(H18-G$12)^2+(I18-H$12)^2+(J18-I$12)^2+(K18-J$12)^2+(L18-K$12)^2 -> 2.8449736 | N18: =N17+M18/SUM(M$16:M$30) -> 0.088162792
A19: ='2_Normalisasi'!A11 -> 4 | B19: ='2_Normalisasi'!B11 -> Candi Mendut | C19: ='2_Normalisasi'!C11 -> 0.15002301 | D19: ='2_Normalisasi'!D11 -> 0.04719284 | E19: ='2_Normalisasi'!E11 -> 0.079378069 | F19: ='2_Normalisasi'!F11 -> 0.5 | G19: ='2_Normalisasi'!G11 -> 0.66666667 | H19: ='2_Normalisasi'!H11 -> 0.66666667 | ... L19: ='2_Normalisasi'!L11 -> 0.14324324 | M19: =(C19-B$12)^2+(D19-C$12)^2+(E19-D$12)^2+(F19-E$12)^2+(G19-F$12)^2+(H19-G$12)^2+(I19-H$12)^2+(J19-I$12)^2+(K19-J$12)^2+(L19-K$12)^2 -> 2.3447193 | N19: =N18+M19/SUM(M$16:M$30) -> 0.12567716
A20: ='2_Normalisasi'!A12 -> 5 | B20: ='2_Normalisasi'!B12 -> Ketep Pass | C20: ='2_Normalisasi'!C12 -> 0.28163829 | D20: ='2_Normalisasi'!D12 -> 0.10781123 | E20: ='2_Normalisasi'!E12 -> 0.14893617 | F20: ='2_Normalisasi'!F12 -> 0.66666667 | G20: ='2_Normalisasi'!G12 -> 0.33333333 | H20: ='2_Normalisasi'!H12 -> 0.66666667 | ... L20: ='2_Normalisasi'!L12 -> 0.31081081 | M20: =(C20-B$12)^2+(D20-C$12)^2+(E20-D$12)^2+(F20-E$12)^2+(G20-F$12)^2+(H20-G$12)^2+(I20-H$12)^2+(J20-I$12)^2+(K20-J$12)^2+(L20-K$12)^2 -> 2.7316489 | N20: =N19+M20/SUM(M$16:M$30) -> 0.1693822
A21: ='2_Normalisasi'!A13 -> 6 | B21: ='2_Normalisasi'!B13 -> Kopeng | C21: ='2_Normalisasi'!C13 -> 0.94799816 | D21: ='2_Normalisasi'!D13 -> 0.86533767 | E21: ='2_Normalisasi'!E13 -> 0.057283142 | F21: ='2_Normalisasi'!F13 -> 0.083333333 | G21: ='2_Normalisasi'!G13 -> 0.33333333 | H21: ='2_Normalisasi'!H13 -> 0.33333333 | ... L21: ='2_Normalisasi'!L13 -> 0.02972973 | M21: =(C21-B$12)^2+(D21-C$12)^2+(E21-D$12)^2+(F21-E$12)^2+(G21-F$12)^2+(H21-G$12)^2+(I21-H$12)^2+(J21-I$12)^2+(K21-J$12)^2+(L21-K$12)^2 -> 6.1441366 | N21: =N20+M21/SUM(M$16:M$30) -> 0.26768539
A22: ='2_Normalisasi'!A14 -> 7 | B22: ='2_Normalisasi'!B14 -> Air Terjun Kedung Kayang | C22: ='2_Normalisasi'!C14 -> 0.33916245 | D22: ='2_Normalisasi'!D14 -> 0.16273393 | E22: ='2_Normalisasi'!E14 -> 0.011456628 | F22: ='2_Normalisasi'!F14 -> 0.58333333 | G22: ='2_Normalisasi'!G14 -> 0 | H22: ='2_Normalisasi'!H14 -> 0 | ... L22: ='2_Normalisasi'!L14 -> 0.48378378 | M22: =(C22-B$12)^2+(D22-C$12)^2+(E22-D$12)^2+(F22-E$12)^2+(G22-F$12)^2+(H22-G$12)^2+(I22-H$12)^2+(J22-I$12)^2+(K22-J$12)^2+(L22-K$12)^2 -> 5.432422 | N22: =N21+M22/SUM(M$16:M$30) -> 0.35460149
A23: ='2_Normalisasi'!A15 -> 8 | B23: ='2_Normalisasi'!B15 -> Telaga Bleder | C23: ='2_Normalisasi'!C15 -> 0.58122411 | D23: ='2_Normalisasi'!D15 -> 0.52441009 | E23: ='2_Normalisasi'!E15 -> 0.0057283142 | F23: ='2_Normalisasi'!F15 -> 0.16666667 | G23: ='2_Normalisasi'!G15 -> 0 | H23: ='2_Normalisasi'!H15 -> 0 | ... L23: ='2_Normalisasi'!L15 -> 0.20540541 | M23: =(C23-B$12)^2+(D23-C$12)^2+(E23-D$12)^2+(F23-E$12)^2+(G23-F$12)^2+(H23-G$12)^2+(I23-H$12)^2+(J23-I$12)^2+(K23-J$12)^2+(L23-K$12)^2 -> 6.2305494 | N23: =N22+M23/SUM(M$16:M$30) -> 0.45428724
A24: ='2_Normalisasi'!A16 -> 9 | B24: ='2_Normalisasi'!B16 -> Bukit Rhema (Gereja Ayam) | C24: ='2_Normalisasi'!C16 -> 0.031753336 | D24: ='2_Normalisasi'!D16 -> 0.030105777 | E24: ='2_Normalisasi'!E16 -> 0.11211129 | F24: ='2_Normalisasi'!F16 -> 0.75 | G24: ='2_Normalisasi'!G16 -> 0.33333333 | H24: ='2_Normalisasi'!H16 -> 0.33333333 | ... L24: ='2_Normalisasi'!L16 -> 0.83783784 | M24: =(C24-B$12)^2+(D24-C$12)^2+(E24-D$12)^2+(F24-E$12)^2+(G24-F$12)^2+(H24-G$12)^2+(I24-H$12)^2+(J24-I$12)^2+(K24-J$12)^2+(L24-K$12)^2 -> 3.0382473 | N24: =N23+M24/SUM(M$16:M$30) -> 0.50289771
A25: ='2_Normalisasi'!A17 -> 10 | B25: ='2_Normalisasi'!B17 -> Sawah Sukomakmur | C25: ='2_Normalisasi'!C17 -> 0.17579383 | D25: ='2_Normalisasi'!D17 -> 0.16842962 | E25: ='2_Normalisasi'!E17 -> 0 | F25: ='2_Normalisasi'!F17 -> 0.33333333 | G25: ='2_Normalisasi'!G17 -> 0 | H25: ='2_Normalisasi'!H17 -> 0 | ... L25: ='2_Normalisasi'!L17 -> 0.65405405 | M25: =(C25-B$12)^2+(D25-C$12)^2+(E25-D$12)^2+(F25-E$12)^2+(G25-F$12)^2+(H25-G$12)^2+(I25-H$12)^2+(J25-I$12)^2+(K25-J$12)^2+(L25-K$12)^2 -> 5.2320496 | N25: =N24+M25/SUM(M$16:M$30) -> 0.58660795
A26: ='2_Normalisasi'!A18 -> 11 | B26: ='2_Normalisasi'!B18 -> Museum Karmawibhangga | C26: ='2_Normalisasi'!C18 -> 0.040036815 | D26: ='2_Normalisasi'!D18 -> 0.012205045 | E26: ='2_Normalisasi'!E18 -> 0.048281506 | F26: ='2_Normalisasi'!F18 -> 0.25 | G26: ='2_Normalisasi'!G18 -> 1 | H26: ='2_Normalisasi'!H18 -> 0.66666667 | ... L26: ='2_Normalisasi'!L18 -> 0.051351351 | M26: =(C26-B$12)^2+(D26-C$12)^2+(E26-D$12)^2+(F26-E$12)^2+(G26-F$12)^2+(H26-G$12)^2+(I26-H$12)^2+(J26-I$12)^2+(K26-J$12)^2+(L26-K$12)^2 -> 3.0043699 | N26: =N25+M26/SUM(M$16:M$30) -> 0.6346764
A27: ='2_Normalisasi'!A19 -> 12 | B27: ='2_Normalisasi'!B19 -> Taman Kyai Langgeng | C27: ='2_Normalisasi'!C19 -> 0.10308329 | D27: ='2_Normalisasi'!D19 -> 0.56590724 | E27: ='2_Normalisasi'!E19 -> 0.095744681 | F27: ='2_Normalisasi'!F19 -> 0 | G27: ='2_Normalisasi'!G19 -> 0.66666667 | H27: ='2_Normalisasi'!H19 -> 0.66666667 | ... L27: ='2_Normalisasi'!L19 -> 0 | M27: =(C27-B$12)^2+(D27-C$12)^2+(E27-D$12)^2+(F27-E$12)^2+(G27-F$12)^2+(H27-G$12)^2+(I27-H$12)^2+(J27-I$12)^2+(K27-J$12)^2+(L27-K$12)^2 -> 3.7814158 | N27: =N26+M27/SUM(M$16:M$30) -> 0.6951772
A28: ='2_Normalisasi'!A20 -> 13 | B28: ='2_Normalisasi'!B20 -> Gunung Andong | C28: ='2_Normalisasi'!C20 -> 1 | D28: ='2_Normalisasi'!D20 -> 0.71440195 | E28: ='2_Normalisasi'!E20 -> 0.022094926 | F28: ='2_Normalisasi'!F20 -> 0.66666667 | G28: ='2_Normalisasi'!G20 -> 0 | H28: ='2_Normalisasi'!H20 -> 0 | ... L28: ='2_Normalisasi'!L20 -> 0.74054054 | M28: =(C28-B$12)^2+(D28-C$12)^2+(E28-D$12)^2+(F28-E$12)^2+(G28-F$12)^2+(H28-G$12)^2+(I28-H$12)^2+(J28-I$12)^2+(K28-J$12)^2+(L28-K$12)^2 -> 6.8424433 | N28: =N27+M28/SUM(M$16:M$30) -> 0.80465295
... A30: ='2_Normalisasi'!A22 -> 15 | B30: ='2_Normalisasi'!B22 -> Puthuk Mongkrong | C30: ='2_Normalisasi'!C22 -> 0.021168891 | D30: ='2_Normalisasi'!D22 -> 0.050854353 | E30: ='2_Normalisasi'!E22 -> 0.01391162 | F30: ='2_Normalisasi'!F22 -> 0.5 | G30: ='2_Normalisasi'!G22 -> 0 | H30: ='2_Normalisasi'!H22 -> 0 | ... L30: ='2_Normalisasi'!L22 -> 1 | M30: =(C30-B$12)^2+(D30-C$12)^2+(E30-D$12)^2+(F30-E$12)^2+(G30-F$12)^2+(H30-G$12)^2+(I30-H$12)^2+(J30-I$12)^2+(K30-J$12)^2+(L30-K$12)^2 -> 5.0379002 | N30: =N29+M30/SUM(M$16:M$30) -> 1
L31: Total D² | M31: =SUM(M16:M30) -> 62.501908
A33: LANGKAH 3: Pilih C2 – Titik dengan D²(x,C1) MAKSIMUM (probabilitas tertinggi untuk dipilih)
A34: C2 = ID argmax D² | C34: =INDEX('2_Normalisasi'!A8:A22,MATCH(MAX(M16:M30),M16:M30,0)) -> 14
A35: Nama Destinasi | C35: =INDEX('2_Normalisasi'!B8:B22,MATCH(MAX(M16:M30),M16:M30,0)) -> Umbul Songo
A36: C2 Values | B36: Lon_n | C36: Lat_n | D36: Visit_n | E36: Rating_n | F36: Akses_n | G36: Fas_n | H36: Alam_n | I36: Budaya_n | J36: Pend_n | K36: Trend_n
B37: =INDEX('2_Normalisasi'!C8:C22,MATCH(MAX(M16:M30),M16:M30,0)) -> 0.88541187 | C37: =INDEX('2_Normalisasi'!D8:D22,MATCH(MAX(M16:M30),M16:M30,0)) -> 1 | D37: =INDEX('2_Normalisasi'!E8:E22,MATCH(MAX(M16:M30),M16:M30,0)) -> 0.0032733224 | E37: =INDEX('2_Normalisasi'!F8:F22,MATCH(MAX(M16:M30),M16:M30,0)) -> 0.41666667 | F37: =INDEX('2_Normalisasi'!G8:G22,MATCH(MAX(M16:M30),M16:M30,0)) -> 0 | G37: =INDEX('2_Normalisasi'!H8:H22,MATCH(MAX(M16:M30),M16:M30,0)) -> 0 | H37: =INDEX('2_Normalisasi'!I8:I22,MATCH(MAX(M16:M30),M16:M30,0)) -> 1 | I37: =INDEX('2_Normalisasi'!J8:J22,MATCH(MAX(M16:M30),M16:M30,0)) -> 0 | J37: =INDEX('2_Normalisasi'!K8:K22,MATCH(MAX(M16:M30),M16:M30,0)) -> 0.001913614 | K37: =INDEX('2_Normalisasi'!L8:L22,MATCH(MAX(M16:M30),M16:M30,0)) -> 0.42162162
A39: LANGKAH 4: Hitung D²_min = min(D²(x,C1), D²(x,C2)) → Pilih C3 sebagai argmax
A40: ID | B40: Nama | C40: Lon_n | D40: Lat_n | E40: Visit_n | F40: Rating_n | G40: Akses_n | H40: Fas_n | I40: Alam_n | J40: Budaya_n | K40: Pend_n | L40: Trend_n | M40: D²(x,C2) | N40: D²_min | O40: P_cum
A41: ='2_Normalisasi'!A8 -> 1 | B41: ='2_Normalisasi'!B8 -> Candi Borobudur | C41: ='2_Normalisasi'!C8 -> 0.039116429 | D41: ='2_Normalisasi'!D8 -> 0.013425549 | E41: ='2_Normalisasi'!E8 -> 1 | F41: ='2_Normalisasi'!F8 -> 1 | G41: ='2_Normalisasi'!G8 -> 1 | H41: ='2_Normalisasi'!H8 -> 1 | ... L41: ='2_Normalisasi'!L8 -> 0.21891892 | M41: =(C41-B$37)^2+(D41-C$37)^2+(E41-D$37)^2+(F41-E$37)^2+(G41-F$37)^2+(H41-G$37)^2+(I41-H$37)^2+(J41-I$37)^2+(K41-J$37)^2+(L41-K$37)^2 -> 7.1716629 | N41: =MIN('3_KMeans++_Init'!M16,'3_KMeans++_Init'!M41) -> 0 | O41: =N41/SUM(N$41:N$55) -> 0
A42: ='2_Normalisasi'!A9 -> 2 | B42: ='2_Normalisasi'!B9 -> Punthuk Setumbu | C42: ='2_Normalisasi'!C9 -> 0 | D42: ='2_Normalisasi'!D9 -> 0.03539463 | E42: ='2_Normalisasi'!E9 -> 0.12847791 | F42: ='2_Normalisasi'!F9 -> 0.83333333 | G42: ='2_Normalisasi'!G9 -> 0.33333333 | H42: ='2_Normalisasi'!H9 -> 0.33333333 | ... L42: ='2_Normalisasi'!L9 -> 0.38648649 | M42: =(C42-B$37)^2+(D42-C$37)^2+(E42-D$37)^2+(F42-E$37)^2+(G42-F$37)^2+(H42-G$37)^2+(I42-H$37)^2+(J42-I$37)^2+(K42-J$37)^2+(L42-K$37)^2 -> 2.5911205 | N42: =MIN('3_KMeans++_Init'!M17,'3_KMeans++_Init'!M42) -> 2.5911205 | O42: =O41+N42/SUM(N$41:N$55) -> 0.10639651
A43: ='2_Normalisasi'!A10 -> 3 | B43: ='2_Normalisasi'!B10 -> Candi Pawon | C43: ='2_Normalisasi'!C10 -> 0.070409572 | D43: ='2_Normalisasi'!D10 -> 0 | E43: ='2_Normalisasi'!E10 -> 0.054828151 | F43: ='2_Normalisasi'!F10 -> 0.41666667 | G43: ='2_Normalisasi'!G10 -> 0.66666667 | H43: ='2_Normalisasi'!H10 -> 0.33333333 | ... L43: ='2_Normalisasi'!L10 -> 0.10810811 | M43: =(C43-B$37)^2+(D43-C$37)^2+(E43-D$37)^2+(F43-E$37)^2+(G43-F$37)^2+(H43-G$37)^2+(I43-H$37)^2+(J43-I$37)^2+(K43-J$37)^2+(L43-K$37)^2 -> 3.7662715 | N43: =MIN('3_KMeans++_Init'!M18,'3_KMeans++_Init'!M43) -> 2.8449736 | O43: =O42+N43/SUM(N$41:N$55) -> 0.22321674
A44: ='2_Normalisasi'!A11 -> 4 | B44: ='2_Normalisasi'!B11 -> Candi Mendut | C44: ='2_Normalisasi'!C11 -> 0.15002301 | D44: ='2_Normalisasi'!D11 -> 0.04719284 | E44: ='2_Normalisasi'!E11 -> 0.079378069 | F44: ='2_Normalisasi'!F11 -> 0.5 | G44: ='2_Normalisasi'!G11 -> 0.66666667 | H44: ='2_Normalisasi'!H11 -> 0.66666667 | ... L44: ='2_Normalisasi'!L11 -> 0.14324324 | M44: =(C44-B$37)^2+(D44-C$37)^2+(E44-D$37)^2+(F44-E$37)^2+(G44-F$37)^2+(H44-G$37)^2+(I44-H$37)^2+(J44-I$37)^2+(K44-J$37)^2+(L44-K$37)^2 -> 3.8749288 | N44: =MIN('3_KMeans++_Init'!M19,'3_KMeans++_Init'!M44) -> 2.3447193 | O44: =O43+N44/SUM(N$41:N$55) -> 0.31949553
A45: ='2_Normalisasi'!A12 -> 5 | B45: ='2_Normalisasi'!B12 -> Ketep Pass | C45: ='2_Normalisasi'!C12 -> 0.28163829 | D45: ='2_Normalisasi'!D12 -> 0.10781123 | E45: ='2_Normalisasi'!E12 -> 0.14893617 | F45: ='2_Normalisasi'!F12 -> 0.66666667 | G45: ='2_Normalisasi'!G12 -> 0.33333333 | H45: ='2_Normalisasi'!H12 -> 0.66666667 | ... L45: ='2_Normalisasi'!L12 -> 0.31081081 | M45: =(C45-B$37)^2+(D45-C$37)^2+(E45-D$37)^2+(F45-E$37)^2+(G45-F$37)^2+(H45-G$37)^2+(I45-H$37)^2+(J45-I$37)^2+(K45-J$37)^2+(L45-K$37)^2 -> 1.9475727 | N45: =MIN('3_KMeans++_Init'!M20,'3_KMeans++_Init'!M45) -> 1.9475727 | O45: =O44+N45/SUM(N$41:N$55) -> 0.39946671
A46: ='2_Normalisasi'!A13 -> 6 | B46: ='2_Normalisasi'!B13 -> Kopeng | C46: ='2_Normalisasi'!C13 -> 0.94799816 | D46: ='2_Normalisasi'!D13 -> 0.86533767 | E46: ='2_Normalisasi'!E13 -> 0.057283142 | F46: ='2_Normalisasi'!F13 -> 0.083333333 | G46: ='2_Normalisasi'!G13 -> 0.33333333 | H46: ='2_Normalisasi'!H13 -> 0.33333333 | ... L46: ='2_Normalisasi'!L13 -> 0.02972973 | M46: =(C46-B$37)^2+(D46-C$37)^2+(E46-D$37)^2+(F46-E$37)^2+(G46-F$37)^2+(H46-G$37)^2+(I46-H$37)^2+(J46-I$37)^2+(K46-J$37)^2+(L46-K$37)^2 -> 0.62384736 | N46: =MIN('3_KMeans++_Init'!M21,'3_KMeans++_Init'!M46) -> 0.62384736 | O46: =O45+N46/SUM(N$41:N$55) -> 0.42508311
...

Sheet 4_Iterasi_KMeans++
A1: ITERASI K-MEANS++: PENUGASAN KLASTER DAN UPDATE CENTROID
A2: Algoritma: (1) Hitung jarak Euclidean ke setiap centroid → (2) Assign ke centroid terdekat → (3) Update centroid = mean klaster → (4) Ulangi hingga konvergen
A4: Centroid | C4: Lon_n | D4: Lat_n | E4: Visit_n | F4: Rating_n | G4: Akses_n | H4: Fas_n | I4: Alam_n | J4: Budaya_n | K4: Pend_n | L4: Trend_n
A5: C1 (Iter-0) | C5: ='3_KMeans++_Init'!B12 -> 0.039116429 | D5: ='3_KMeans++_Init'!C12 -> 0.013425549 | E5: ='3_KMeans++_Init'!D12 -> 1 | F5: ='3_KMeans++_Init'!E12 -> 1 | G5: ='3_KMeans++_Init'!F12 -> 1 | H5: ='3_KMeans++_Init'!G12 -> 1 | I5: ='3_KMeans++_Init'!H12 -> 0.66666667 | J5: ='3_KMeans++_Init'!I12 -> 1 | ... L5: ='3_KMeans++_Init'!K12 -> 0.21891892
A6: C2 (Iter-0) | C6: ='3_KMeans++_Init'!B37 -> 0.88541187 | D6: ='3_KMeans++_Init'!C37 -> 1 | E6: ='3_KMeans++_Init'!D37 -> 0.0032733224 | F6: ='3_KMeans++_Init'!E37 -> 0.41666667 | G6: ='3_KMeans++_Init'!F37 -> 0 | H6: ='3_KMeans++_Init'!G37 -> 0 | I6: ='3_KMeans++_Init'!H37 -> 1 | J6: ='3_KMeans++_Init'!I37 -> 0 | ... L6: ='3_KMeans++_Init'!K37 -> 0.42162162
A7: C3 (Iter-0) | C7: ='3_KMeans++_Init'!B59 -> 0.040036815 | D7: ='3_KMeans++_Init'!C59 -> 0.012205045 | E7: ='3_KMeans++_Init'!D59 -> 0.048281506 | F7: ='3_KMeans++_Init'!E59 -> 0.25 | G7: ='3_KMeans++_Init'!F59 -> 1 | H7: ='3_KMeans++_Init'!G59 -> 0.66666667 | I7: ='3_KMeans++_Init'!H59 -> 0 | J7: ='3_KMeans++_Init'!I59 -> 1 | ... L7: ='3_KMeans++_Init'!K59 -> 0.051351351
A9: ITERASI 1 – PENUGASAN: Hitung jarak ke C1, C2, C3 → assign klaster
A10: ID | B10: Nama | C10: Lon_n | D10: Lat_n | E10: Visit_n | F10: Rating_n | G10: Akses_n | H10: Fas_n | I10: Alam_n | J10: Budaya_n | K10: Pend_n | L10: Trend_n | M10: d(x,C1) | N10: d(x,C2) | O10: d(x,C3) | P10: Klaster | Q10: Warna
A11: ='2_Normalisasi'!A8 -> 1 | B11: ='2_Normalisasi'!B8 -> Candi Borobudur | C11: ='2_Normalisasi'!C8 -> 0.039116429 | D11: ='2_Normalisasi'!D8 -> 0.013425549 | E11: ='2_Normalisasi'!E8 -> 1 | F11: ='2_Normalisasi'!F8 -> 1 | G11: ='2_Normalisasi'!G8 -> 1 | H11: ='2_Normalisasi'!H8 -> 1 | ... L11: ='2_Normalisasi'!L8 -> 0.21891892 | M11: =SQRT((C11-C$5)^2+(D11-D$5)^2+(E11-E$5)^2+(F11-F$5)^2+(G11-G$5)^2+(H11-H$5)^2+(I11-I$5)^2+(J11-J$5)^2+(K11-K$5)^2+(L11-L$5)^2) -> 0 | N11: =SQRT((C11-C$6)^2+(D11-D$6)^2+(E11-E$6)^2+(F11-F$6)^2+(G11-G$6)^2+(H11-H$6)^2+(I11-I$6)^2+(J11-J$6)^2+(K11-K$6)^2+(L11-L$6)^2) -> 2.6779961 | O11: =SQRT((C11-C$7)^2+(D11-D$7)^2+(E11-E$7)^2+(F11-F$7)^2+(G11-G$7)^2+(H11-H$7)^2+(I11-I$7)^2+(J11-J$7)^2+(K11-K$7)^2+(L11-L$7)^2) -> 1.7333118 | P11: =MATCH(MIN(M11:O11),M11:O11,0) -> 1 | Q11: =IF(P11=1,"Klaster 1 (Unggulan)",IF(P11=2,"Klaster 2 (Berkembang)","Klaster 3 (Potensial)")) -> Klaster 1 (Unggulan)
A12: ='2_Normalisasi'!A9 -> 2 | B12: ='2_Normalisasi'!B9 -> Punthuk Setumbu | C12: ='2_Normalisasi'!C9 -> 0 | D12: ='2_Normalisasi'!D9 -> 0.03539463 | E12: ='2_Normalisasi'!E9 -> 0.12847791 | F12: ='2_Normalisasi'!F9 -> 0.83333333 | G12: ='2_Normalisasi'!G9 -> 0.33333333 | H12: ='2_Normalisasi'!H9 -> 0.33333333 | ... L12: ='2_Normalisasi'!L9 -> 0.38648649 | M12: =SQRT((C12-C$5)^2+(D12-D$5)^2+(E12-E$5)^2+(F12-F$5)^2+(G12-G$5)^2+(H12-H$5)^2+(I12-I$5)^2+(J12-J$5)^2+(K12-K$5)^2+(L12-L$5)^2) -> 1.6325958 | N12: =SQRT((C12-C$6)^2+(D12-D$6)^2+(E12-E$6)^2+(F12-F$6)^2+(G12-G$6)^2+(H12-H$6)^2+(I12-I$6)^2+(J12-J$6)^2+(K12-K$6)^2+(L12-L$6)^2) -> 1.6096958 | O12: =SQRT((C12-C$7)^2+(D12-D$7)^2+(E12-E$7)^2+(F12-F$7)^2+(G12-G$7)^2+(H12-H$7)^2+(I12-I$7)^2+(J12-J$7)^2+(K12-K$7)^2+(L12-L$7)^2) -> 1.4634378 | P12: =MATCH(MIN(M12:O12),M12:O12,0) -> 3 | Q12: =IF(P12=1,"Klaster 1 (Unggulan)",IF(P12=2,"Klaster 2 (Berkembang)","Klaster 3 (Potensial)")) -> Klaster 3 (Potensial)
A13: ='2_Normalisasi'!A10 -> 3 | B13: ='2_Normalisasi'!B10 -> Candi Pawon | C13: ='2_Normalisasi'!C10 -> 0.070409572 | D13: ='2_Normalisasi'!D10 -> 0 | E13: ='2_Normalisasi'!E10 -> 0.054828151 | F13: ='2_Normalisasi'!F10 -> 0.41666667 | G13: ='2_Normalisasi'!G10 -> 0.66666667 | H13: ='2_Normalisasi'!H10 -> 0.33333333 | ... L13: ='2_Normalisasi'!L10 -> 0.10810811 | M13: =SQRT((C13-C$5)^2+(D13-D$5)^2+(E13-E$5)^2+(F13-F$5)^2+(G13-G$5)^2+(H13-H$5)^2+(I13-I$5)^2+(J13-J$5)^2+(K13-K$5)^2+(L13-L$5)^2) -> 1.686705 | N13: =SQRT((C13-C$6)^2+(D13-D$6)^2+(E13-E$6)^2+(F13-F$6)^2+(G13-G$6)^2+(H13-H$6)^2+(I13-I$6)^2+(J13-J$6)^2+(K13-K$6)^2+(L13-L$6)^2) -> 1.9406884 | O13: =SQRT((C13-C$7)^2+(D13-D$7)^2+(E13-E$7)^2+(F13-F$7)^2+(G13-G$7)^2+(H13-H$7)^2+(I13-I$7)^2+(J13-J$7)^2+(K13-K$7)^2+(L13-L$7)^2) -> 0.60462082 | P13: =MATCH(MIN(M13:O13),M13:O13,0) -> 3 | Q13: =IF(P13=1,"Klaster 1 (Unggulan)",IF(P13=2,"Klaster 2 (Berkembang)","Klaster 3 (Potensial)")) -> Klaster 3 (Potensial)
A14: ='2_Normalisasi'!A11 -> 4 | B14: ='2_Normalisasi'!B11 -> Candi Mendut | C14: ='2_Normalisasi'!C11 -> 0.15002301 | D14: ='2_Normalisasi'!D11 -> 0.04719284 | E14: ='2_Normalisasi'!E11 -> 0.079378069 | F14: ='2_Normalisasi'!F11 -> 0.5 | G14: ='2_Normalisasi'!G11 -> 0.66666667 | H14: ='2_Normalisasi'!H11 -> 0.66666667 | ... L14: ='2_Normalisasi'!L11 -> 0.14324324 | M14: =SQRT((C14-C$5)^2+(D14-D$5)^2+(E14-E$5)^2+(F14-F$5)^2+(G14-G$5)^2+(H14-H$5)^2+(I14-I$5)^2+(J14-J$5)^2+(K14-K$5)^2+(L14-L$5)^2) -> 1.5312476 | N14: =SQRT((C14-C$6)^2+(D14-D$6)^2+(E14-E$6)^2+(F14-F$6)^2+(G14-G$6)^2+(H14-H$6)^2+(I14-I$6)^2+(J14-J$6)^2+(K14-K$6)^2+(L14-L$6)^2) -> 1.9684839 | O14: =SQRT((C14-C$7)^2+(D14-D$7)^2+(E14-E$7)^2+(F14-F$7)^2+(G14-G$7)^2+(H14-H$7)^2+(I14-I$7)^2+(J14-J$7)^2+(K14-K$7)^2+(L14-L$7)^2) -> 0.55530056 | P14: =MATCH(MIN(M14:O14),M14:O14,0) -> 3 | Q14: =IF(P14=1,"Klaster 1 (Unggulan)",IF(P14=2,"Klaster 2 (Berkembang)","Klaster 3 (Potensial)")) -> Klaster 3 (Potensial)
A15: ='2_Normalisasi'!A12 -> 5 | B15: ='2_Normalisasi'!B12 -> Ketep Pass | C15: ='2_Normalisasi'!C12 -> 0.28163829 | D15: ='2_Normalisasi'!D12 -> 0.10781123 | E15: ='2_Normalisasi'!E12 -> 0.14893617 | F15: ='2_Normalisasi'!F12 -> 0.66666667 | G15: ='2_Normalisasi'!G12 -> 0.33333333 | H15: ='2_Normalisasi'!H12 -> 0.66666667 | ... L15: ='2_Normalisasi'!L12 -> 0.31081081 | M15: =SQRT((C15-C$5)^2+(D15-D$5)^2+(E15-E$5)^2+(F15-F$5)^2+(G15-G$5)^2+(H15-H$5)^2+(I15-I$5)^2+(J15-J$5)^2+(K15-K$5)^2+(L15-L$5)^2) -> 1.6527701 | N15: =SQRT((C15-C$6)^2+(D15-D$6)^2+(E15-E$6)^2+(F15-F$6)^2+(G15-G$6)^2+(H15-H$6)^2+(I15-I$6)^2+(J15-J$6)^2+(K15-K$6)^2+(L15-L$6)^2) -> 1.3955546 | O15: =SQRT((C15-C$7)^2+(D15-D$7)^2+(E15-E$7)^2+(F15-F$7)^2+(G15-G$7)^2+(H15-H$7)^2+(I15-I$7)^2+(J15-J$7)^2+(K15-K$7)^2+(L15-L$7)^2) -> 1.4917794 | P15: =MATCH(MIN(M15:O15),M15:O15,0) -> 2 | Q15: =IF(P15=1,"Klaster 1 (Unggulan)",IF(P15=2,"Klaster 2 (Berkembang)","Klaster 3 (Potensial)")) -> Klaster 2 (Berkembang)
A16: ='2_Normalisasi'!A13 -> 6 | B16: ='2_Normalisasi'!B13 -> Kopeng | C16: ='2_Normalisasi'!C13 -> 0.94799816 | D16: ='2_Normalisasi'!D13 -> 0.86533767 | E16: ='2_Normalisasi'!E13 -> 0.057283142 | F16: ='2_Normalisasi'!F13 -> 0.083333333 | G16: ='2_Normalisasi'!G13 -> 0.33333333 | H16: ='2_Normalisasi'!H13 -> 0.33333333 | ... L16: ='2_Normalisasi'!L13 -> 0.02972973 | M16: =SQRT((C16-C$5)^2+(D16-D$5)^2+(E16-E$5)^2+(F16-F$5)^2+(G16-G$5)^2+(H16-H$5)^2+(I16-I$5)^2+(J16-J$5)^2+(K16-K$5)^2+(L16-L$5)^2) -> 2.4787369 | N16: =SQRT((C16-C$6)^2+(D16-D$6)^2+(E16-E$6)^2+(F16-F$6)^2+(G16-G$6)^2+(H16-H$6)^2+(I16-I$6)^2+(J16-J$6)^2+(K16-K$6)^2+(L16-L$6)^2) -> 0.78984009 | O16: =SQRT((C16-C$7)^2+(D16-D$7)^2+(E16-E$7)^2+(F16-F$7)^2+(G16-G$7)^2+(H16-H$7)^2+(I16-I$7)^2+(J16-J$7)^2+(K16-K$7)^2+(L16-L$7)^2) -> 1.8922489 | P16: =MATCH(MIN(M16:O16),M16:O16,0) -> 2 | Q16: =IF(P16=1,"Klaster 1 (Unggulan)",IF(P16=2,"Klaster 2 (Berkembang)","Klaster 3 (Potensial)")) -> Klaster 2 (Berkembang)
A17: ='2_Normalisasi'!A14 -> 7 | B17: ='2_Normalisasi'!B14 -> Air Terjun Kedung Kayang | C17: ='2_Normalisasi'!C14 -> 0.33916245 | D17: ='2_Normalisasi'!D14 -> 0.16273393 | E17: ='2_Normalisasi'!E14 -> 0.011456628 | F17: ='2_Normalisasi'!F14 -> 0.58333333 | G17: ='2_Normalisasi'!G14 -> 0 | H17: ='2_Normalisasi'!H14 -> 0 | ... L17: ='2_Normalisasi'!L14 -> 0.48378378 | M17: =SQRT((C17-C$5)^2+(D17-D$5)^2+(E17-E$5)^2+(F17-F$5)^2+(G17-G$5)^2+(H17-H$5)^2+(I17-I$5)^2+(J17-J$5)^2+(K17-K$5)^2+(L17-L$5)^2) -> 2.3307557 | N17: =SQRT((C17-C$6)^2+(D17-D$6)^2+(E17-E$6)^2+(F17-F$6)^2+(G17-G$6)^2+(H17-H$6)^2+(I17-I$6)^2+(J17-J$6)^2+(K17-K$6)^2+(L17-L$6)^2) -> 1.015445 | O17: =SQRT((C17-C$7)^2+(D17-D$7)^2+(E17-E$7)^2+(F17-F$7)^2+(G17-G$7)^2+(H17-H$7)^2+(I17-I$7)^2+(J17-J$7)^2+(K17-K$7)^2+(L17-L$7)^2) -> 1.9637643 | P17: =MATCH(MIN(M17:O17),M17:O17,0) -> 2 | Q17: =IF(P17=1,"Klaster 1 (Unggulan)",IF(P17=2,"Klaster 2 (Berkembang)","Klaster 3 (Potensial)")) -> Klaster 2 (Berkembang)
A18: ='2_Normalisasi'!A15 -> 8 | B18: ='2_Normalisasi'!B15 -> Telaga Bleder | C18: ='2_Normalisasi'!C15 -> 0.58122411 | D18: ='2_Normalisasi'!D15 -> 0.52441009 | E18: ='2_Normalisasi'!E15 -> 0.0057283142 | F18: ='2_Normalisasi'!F15 -> 0.16666667 | G18: ='2_Normalisasi'!G15 -> 0 | H18: ='2_Normalisasi'!H15 -> 0 | ... L18: ='2_Normalisasi'!L15 -> 0.20540541 | M18: =SQRT((C18-C$5)^2+(D18-D$5)^2+(E18-E$5)^2+(F18-F$5)^2+(G18-G$5)^2+(H18-H$5)^2+(I18-I$5)^2+(J18-J$5)^2+(K18-K$5)^2+(L18-L$5)^2) -> 2.4961068 | N18: =SQRT((C18-C$6)^2+(D18-D$6)^2+(E18-E$6)^2+(F18-F$6)^2+(G18-G$6)^2+(H18-H$6)^2+(I18-I$6)^2+(J18-J$6)^2+(K18-K$6)^2+(L18-L$6)^2) -> 0.7342249 | O18: =SQRT((C18-C$7)^2+(D18-D$7)^2+(E18-E$7)^2+(F18-F$7)^2+(G18-G$7)^2+(H18-H$7)^2+(I18-I$7)^2+(J18-J$7)^2+(K18-K$7)^2+(L18-L$7)^2) -> 1.8646779 | P18: =MATCH(MIN(M18:O18),M18:O18,0) -> 2 | Q18: =IF(P18=1,"Klaster 1 (Unggulan)",IF(P18=2,"Klaster 2 (Berkembang)","Klaster 3 (Potensial)")) -> Klaster 2 (Berkembang)
A19: ='2_Normalisasi'!A16 -> 9 | B19: ='2_Normalisasi'!B16 -> Bukit Rhema (Gereja Ayam) | C19: ='2_Normalisasi'!C16 -> 0.031753336 | D19: ='2_Normalisasi'!D16 -> 0.030105777 | E19: ='2_Normalisasi'!E16 -> 0.11211129 | F19: ='2_Normalisasi'!F16 -> 0.75 | G19: ='2_Normalisasi'!G16 -> 0.33333333 | H19: ='2_Normalisasi'!H16 -> 0.33333333 | ... L19: ='2_Normalisasi'!L16 -> 0.83783784 | M19: =SQRT((C19-C$5)^2+(D19-D$5)^2+(E19-E$5)^2+(F19-F$5)^2+(G19-G$5)^2+(H19-H$5)^2+(I19-I$5)^2+(J19-J$5)^2+(K19-K$5)^2+(L19-L$5)^2) -> 1.7430569 | N19: =SQRT((C19-C$6)^2+(D19-D$6)^2+(E19-E$6)^2+(F19-F$6)^2+(G19-G$6)^2+(H19-H$6)^2+(I19-I$6)^2+(J19-J$6)^2+(K19-K$6)^2+(L19-L$6)^2) -> 1.659423 | O19: =SQRT((C19-C$7)^2+(D19-D$7)^2+(E19-E$7)^2+(F19-F$7)^2+(G19-G$7)^2+(H19-H$7)^2+(I19-I$7)^2+(J19-J$7)^2+(K19-K$7)^2+(L19-L$7)^2) -> 1.4108226 | P19: =MATCH(MIN(M19:O19),M19:O19,0) -> 3 | Q19: =IF(P19=1,"Klaster 1 (Unggulan)",IF(P19=2,"Klaster 2 (Berkembang)","Klaster 3 (Potensial)")) -> Klaster 3 (Potensial)
A20: ='2_Normalisasi'!A17 -> 10 | B20: ='2_Normalisasi'!B17 -> Sawah Sukomakmur | C20: ='2_Normalisasi'!C17 -> 0.17579383 | D20: ='2_Normalisasi'!D17 -> 0.16842962 | E20: ='2_Normalisasi'!E17 -> 0 | F20: ='2_Normalisasi'!F17 -> 0.33333333 | G20: ='2_Normalisasi'!G17 -> 0 | H20: ='2_Normalisasi'!H17 -> 0 | ... L20: ='2_Normalisasi'!L17 -> 0.65405405 | M20: =SQRT((C20-C$5)^2+(D20-D$5)^2+(E20-E$5)^2+(F20-F$5)^2+(G20-G$5)^2+(H20-H$5)^2+(I20-I$5)^2+(J20-J$5)^2+(K20-K$5)^2+(L20-L$5)^2) -> 2.2873674 | N20: =SQRT((C20-C$6)^2+(D20-D$6)^2+(E20-E$6)^2+(F20-F$6)^2+(G20-G$6)^2+(H20-H$6)^2+(I20-I$6)^2+(J20-J$6)^2+(K20-K$6)^2+(L20-L$6)^2) -> 1.169257 | O20: =SQRT((C20-C$7)^2+(D20-D$7)^2+(E20-E$7)^2+(F20-F$7)^2+(G20-G$7)^2+(H20-H$7)^2+(I20-I$7)^2+(J20-J$7)^2+(K20-K$7)^2+(L20-L$7)^2) -> 1.8179191 | P20: =MATCH(MIN(M20:O20),M20:O20,0) -> 2 | Q20: =IF(P20=1,"Klaster 1 (Unggulan)",IF(P20=2,"Klaster 2 (Berkembang)","Klaster 3 (Potensial)")) -> Klaster 2 (Berkembang)
A21: ='2_Normalisasi'!A18 -> 11 | B21: ='2_Normalisasi'!B18 -> Museum Karmawibhangga | C21: ='2_Normalisasi'!C18 -> 0.040036815 | D21: ='2_Normalisasi'!D18 -> 0.012205045 | E21: ='2_Normalisasi'!E18 -> 0.048281506 | F21: ='2_Normalisasi'!F18 -> 0.25 | G21: ='2_Normalisasi'!G18 -> 1 | H21: ='2_Normalisasi'!H18 -> 0.66666667 | ... L21: ='2_Normalisasi'!L18 -> 0.051351351 | M21: =SQRT((C21-C$5)^2+(D21-D$5)^2+(E21-E$5)^2+(F21-F$5)^2+(G21-G$5)^2+(H21-H$5)^2+(I21-I$5)^2+(J21-J$5)^2+(K21-K$5)^2+(L21-L$5)^2) -> 1.7333118 | N21: =SQRT((C21-C$6)^2+(D21-D$6)^2+(E21-E$6)^2+(F21-F$6)^2+(G21-G$6)^2+(H21-H$6)^2+(I21-I$6)^2+(J21-J$6)^2+(K21-K$6)^2+(L21-L$6)^2) -> 2.3026585 | O21: =SQRT((C21-C$7)^2+(D21-D$7)^2+(E21-E$7)^2+(F21-F$7)^2+(G21-G$7)^2+(H21-H$7)^2+(I21-I$7)^2+(J21-J$7)^2+(K21-K$7)^2+(L21-L$7)^2) -> 0 | P21: =MATCH(MIN(M21:O21),M21:O21,0) -> 3 | Q21: =IF(P21=1,"Klaster 1 (Unggulan)",IF(P21=2,"Klaster 2 (Berkembang)","Klaster 3 (Potensial)")) -> Klaster 3 (Potensial)
A22: ='2_Normalisasi'!A19 -> 12 | B22: ='2_Normalisasi'!B19 -> Taman Kyai Langgeng | C22: ='2_Normalisasi'!C19 -> 0.10308329 | D22: ='2_Normalisasi'!D19 -> 0.56590724 | E22: ='2_Normalisasi'!E19 -> 0.095744681 | F22: ='2_Normalisasi'!F19 -> 0 | G22: ='2_Normalisasi'!G19 -> 0.66666667 | H22: ='2_Normalisasi'!H19 -> 0.66666667 | ... L22: ='2_Normalisasi'!L19 -> 0 | M22: =SQRT((C22-C$5)^2+(D22-D$5)^2+(E22-E$5)^2+(F22-F$5)^2+(G22-G$5)^2+(H22-H$5)^2+(I22-I$5)^2+(J22-J$5)^2+(K22-K$5)^2+(L22-L$5)^2) -> 1.9445863 | N22: =SQRT((C22-C$6)^2+(D22-D$6)^2+(E22-E$6)^2+(F22-F$6)^2+(G22-G$6)^2+(H22-H$6)^2+(I22-I$6)^2+(J22-J$6)^2+(K22-K$6)^2+(L22-L$6)^2) -> 1.6163373 | O22: =SQRT((C22-C$7)^2+(D22-D$7)^2+(E22-E$7)^2+(F22-F$7)^2+(G22-G$7)^2+(H22-H$7)^2+(I22-I$7)^2+(J22-J$7)^2+(K22-K$7)^2+(L22-L$7)^2) -> 1.0241689 | P22: =MATCH(MIN(M22:O22),M22:O22,0) -> 3 | Q22: =IF(P22=1,"Klaster 1 (Unggulan)",IF(P22=2,"Klaster 2 (Berkembang)","Klaster 3 (Potensial)")) -> Klaster 3 (Potensial)
... A25: ='2_Normalisasi'!A22 -> 15 | B25: ='2_Normalisasi'!B22 -> Puthuk Mongkrong | C25: ='2_Normalisasi'!C22 -> 0.021168891 | D25: ='2_Normalisasi'!D22 -> 0.050854353 | E25: ='2_Normalisasi'!E22 -> 0.01391162 | F25: ='2_Normalisasi'!F22 -> 0.5 | G25: ='2_Normalisasi'!G22 -> 0 | H25: ='2_Normalisasi'!H22 -> 0 | ... L25: ='2_Normalisasi'!L22 -> 1 | M25: =SQRT((C25-C$5)^2+(D25-D$5)^2+(E25-E$5)^2+(F25-F$5)^2+(G25-G$5)^2+(H25-H$5)^2+(I25-I$5)^2+(J25-J$5)^2+(K25-K$5)^2+(L25-L$5)^2) -> 2.2445267 | N25: =SQRT((C25-C$6)^2+(D25-D$6)^2+(E25-E$6)^2+(F25-F$6)^2+(G25-G$6)^2+(H25-H$6)^2+(I25-I$6)^2+(J25-J$6)^2+(K25-K$6)^2+(L25-L$6)^2) -> 1.560087 | O25: =SQRT((C25-C$7)^2+(D25-D$7)^2+(E25-E$7)^2+(F25-F$7)^2+(G25-G$7)^2+(H25-H$7)^2+(I25-I$7)^2+(J25-J$7)^2+(K25-K$7)^2+(L25-L$7)^2) -> 1.8764964 | P25: =MATCH(MIN(M25:O25),M25:O25,0) -> 2 | Q25: =IF(P25=1,"Klaster 1 (Unggulan)",IF(P25=2,"Klaster 2 (Berkembang)","Klaster 3 (Potensial)")) -> Klaster 2 (Berkembang)
A27: UPDATE CENTROID ITERASI 1: Centroid baru = AVERAGE(titik dalam klaster)
A28: Centroid | B28: n(titik) | C28: Lon_n | D28: Lat_n | E28: Visit_n | F28: Rating_n | G28: Akses_n | H28: Fas_n | I28: Alam_n | J28: Budaya_n | K28: Pend_n | L28: Trend_n | M28: WCSS
A29: C1 baru | B29: =COUNTIF(P$11:P$25,1) -> 1 | C29: =IFERROR(AVERAGEIF(P$11:P$25,1,C$11:C$25),0) -> 0.039116429 | D29: =IFERROR(AVERAGEIF(P$11:P$25,1,D$11:D$25),0) -> 0.013425549 | E29: =IFERROR(AVERAGEIF(P$11:P$25,1,E$11:E$25),0) -> 1 | F29: =IFERROR(AVERAGEIF(P$11:P$25,1,F$11:F$25),0) -> 1 | G29: =IFERROR(AVERAGEIF(P$11:P$25,1,G$11:G$25),0) -> 1 | H29: =IFERROR(AVERAGEIF(P$11:P$25,1,H$11:H$25),0) -> 1 | I29: =IFERROR(AVERAGEIF(P$11:P$25,1,I$11:I$25),0) -> 0.66666667 | J29: =IFERROR(AVERAGEIF(P$11:P$25,1,J$11:J$25),0) -> 1 | K29: =IFERROR(AVERAGEIF(P$11:P$25,1,K$11:K$25),0) -> 1 | L29: =IFERROR(AVERAGEIF(P$11:P$25,1,L$11:L$25),0) -> 0.21891892 | M29: =SUMPRODUCT((P$11:P$25=1)*((C$11:C$25-$C$5)^2+(D$11:D$25-$D$5)^2+(E$11:E$25-$E$5)^2+(F$11:F$25-$F$5)^2+(G$11:G$25-$G$5)^2+(H$11:H$25-$H$5)^2+(I$11:I$25-$I$5)^2+(J$11:J$25-$J$5)^2+(K$11:K$25-$K$5)^2+(L$11:L$25-$L$5)^2)) -> 0
A30: C2 baru | B30: =COUNTIF(P$11:P$25,2) -> 8 | C30: =IFERROR(AVERAGEIF(P$11:P$25,2,C$11:C$25),0) -> 0.5290497 | D30: =IFERROR(AVERAGEIF(P$11:P$25,2,D$11:D$25),0) -> 0.44924736 | E30: =IFERROR(AVERAGEIF(P$11:P$25,2,E$11:E$25),0) -> 0.032835516 | F30: =IFERROR(AVERAGEIF(P$11:P$25,2,F$11:F$25),0) -> 0.42708333 | G30: =IFERROR(AVERAGEIF(P$11:P$25,2,G$11:G$25),0) -> 0.083333333 | H30: =IFERROR(AVERAGEIF(P$11:P$25,2,H$11:H$25),0) -> 0.125 | I30: =IFERROR(AVERAGEIF(P$11:P$25,2,I$11:I$25),0) -> 0.91666667 | J30: =IFERROR(AVERAGEIF(P$11:P$25,2,J$11:J$25),0) -> 0.16666667 | K30: =IFERROR(AVERAGEIF(P$11:P$25,2,K$11:K$25),0) -> 0.027713231 | L30: =IFERROR(AVERAGEIF(P$11:P$25,2,L$11:L$25),0) -> 0.48074324 | M30: =SUMPRODUCT((P$11:P$25=2)*((C$11:C$25-$C$6)^2+(D$11:D$25-$D$6)^2+(E$11:E$25-$E$6)^2+(F$11:F$25-$F$6)^2+(G$11:G$25-$G$6)^2+(H$11:H$25-$H$6)^2+(I$11:I$25-$I$6)^2+(J$11:J$25-$J$6)^2+(K$11:K$25-$K$6)^2+(L$11:L$25-$L$6)^2)) -> 8.20202
A31: C3 baru | B31: =COUNTIF(P$11:P$25,3) -> 6 | C31: =IFERROR(AVERAGEIF(P$11:P$25,3,C$11:C$25),0) -> 0.065884338 | D31: =IFERROR(AVERAGEIF(P$11:P$25,3,D$11:D$25),0) -> 0.11513426 | E31: =IFERROR(AVERAGEIF(P$11:P$25,3,E$11:E$25),0) -> 0.086470267 | F31: =IFERROR(AVERAGEIF(P$11:P$25,3,F$11:F$25),0) -> 0.45833333 | G31: =IFERROR(AVERAGEIF(P$11:P$25,3,G$11:G$25),0) -> 0.61111111 | H31: =IFERROR(AVERAGEIF(P$11:P$25,3,H$11:H$25),0) -> 0.5 | I31: =IFERROR(AVERAGEIF(P$11:P$25,3,I$11:I$25),0) -> 0.44444444 | J31: =IFERROR(AVERAGEIF(P$11:P$25,3,J$11:J$25),0) -> 0.77777778 | K31: =IFERROR(AVERAGEIF(P$11:P$25,3,K$11:K$25),0) -> 0.074630946 | L31: =IFERROR(AVERAGEIF(P$11:P$25,3,L$11:L$25),0) -> 0.2545045 | M31: =SUMPRODUCT((P$11:P$25=3)*((C$11:C$25-$C$7)^2+(D$11:D$25-$D$7)^2+(E$11:E$25-$E$7)^2+(F$11:F$25-$F$7)^2+(G$11:G$25-$G$7)^2+(H$11:H$25-$H$7)^2+(I$11:I$25-$I$7)^2+(J$11:J$25-$J$7)^2+(K$11:K$25-$K$7)^2+(L$11:L$25-$L$7)^2)) -> 5.8549178
A33: Total WCSS Iter-1 | C33: =SUM(M29:M31) -> 14.056938
A37: ITERASI 2 – PENUGASAN: Hitung jarak ke C1, C2, C3 → assign klaster
A38: ID | B38: Nama | C38: Lon_n | D38: Lat_n | E38: Visit_n | F38: Rating_n | G38: Akses_n | H38: Fas_n | I38: Alam_n | J38: Budaya_n | K38: Pend_n | L38: Trend_n | M38: d(x,C1) | N38: d(x,C2) | O38: d(x,C3) | P38: Klaster | Q38: Warna
A39: =A11 -> 1 | B39: =B11 -> Candi Borobudur | C39: =C11 -> 0.039116429 | D39: =D11 -> 0.013425549 | E39: =E11 -> 1 | F39: =F11 -> 1 | G39: =G11 -> 1 | H39: =H11 -> 1 | ... L39: =L11 -> 0.21891892 | M39: =SQRT((C39-C$29)^2+(D39-D$29)^2+(E39-E$29)^2+(F39-F$29)^2+(G39-G$29)^2+(H39-H$29)^2+(I39-I$29)^2+(J39-J$29)^2+(K39-K$29)^2+(L39-L$29)^2) -> 0 | N39: =SQRT((C39-C$30)^2+(D39-D$30)^2+(E39-E$30)^2+(F39-F$30)^2+(G39-G$30)^2+(H39-H$30)^2+(I39-I$30)^2+(J39-J$30)^2+(K39-K$30)^2+(L39-L$30)^2) -> 2.2517452 | O39: =SQRT((C39-C$31)^2+(D39-D$31)^2+(E39-E$31)^2+(F39-F$31)^2+(G39-G$31)^2+(H39-H$31)^2+(I39-I$31)^2+(J39-J$31)^2+(K39-K$31)^2+(L39-L$31)^2) -> 1.5800553 | P39: =MATCH(MIN(M39:O39),M39:O39,0) -> 1 | Q39: =IF(P39=1,"Klaster 1 (Unggulan)",IF(P39=2,"Klaster 2 (Berkembang)","Klaster 3 (Potensial)")) -> Klaster 1 (Unggulan)
A40: =A12 -> 2 | B40: =B12 -> Punthuk Setumbu | C40: =C12 -> 0 | D40: =D12 -> 0.03539463 | E40: =E12 -> 0.12847791 | F40: =F12 -> 0.83333333 | G40: =G12 -> 0.33333333 | H40: =H12 -> 0.33333333 | ... L40: =L12 -> 0.38648649 | M40: =SQRT((C40-C$29)^2+(D40-D$29)^2+(E40-E$29)^2+(F40-F$29)^2+(G40-G$29)^2+(H40-H$29)^2+(I40-I$29)^2+(J40-J$29)^2+(K40-K$29)^2+(L40-L$29)^2) -> 1.6325958 | N40: =SQRT((C40-C$30)^2+(D40-D$30)^2+(E40-E$30)^2+(F40-F$30)^2+(G40-G$30)^2+(H40-H$30)^2+(I40-I$30)^2+(J40-J$30)^2+(K40-K$30)^2+(L40-L$30)^2) -> 1.0050162 | O40: =SQRT((C40-C$31)^2+(D40-D$31)^2+(E40-E$31)^2+(F40-F$31)^2+(G40-G$31)^2+(H40-H$31)^2+(I40-I$31)^2+(J40-J$31)^2+(K40-K$31)^2+(L40-L$31)^2) -> 0.77519018 | P40: =MATCH(MIN(M40:O40),M40:O40,0) -> 3 | Q40: =IF(P40=1,"Klaster 1 (Unggulan)",IF(P40=2,"Klaster 2 (Berkembang)","Klaster 3 (Potensial)")) -> Klaster 3 (Potensial)
A41: =A13 -> 3 | B41: =B13 -> Candi Pawon | C41: =C13 -> 0.070409572 | D41: =D13 -> 0 | E41: =E13 -> 0.054828151 | F41: =F13 -> 0.41666667 | G41: =G13 -> 0.66666667 | H41: =H13 -> 0.33333333 | ... L41: =L13 -> 0.10810811 | M41: =SQRT((C41-C$29)^2+(D41-D$29)^2+(E41-E$29)^2+(F41-F$29)^2+(G41-G$29)^2+(H41-H$29)^2+(I41-I$29)^2+(J41-J$29)^2+(K41-K$29)^2+(L41-L$29)^2) -> 1.686705 | N41: =SQRT((C41-C$30)^2+(D41-D$30)^2+(E41-E$30)^2+(F41-F$30)^2+(G41-G$30)^2+(H41-H$30)^2+(I41-I$30)^2+(J41-J$30)^2+(K41-K$30)^2+(L41-L$30)^2) -> 1.403595 | O41: =SQRT((C41-C$31)^2+(D41-D$31)^2+(E41-E$31)^2+(F41-F$31)^2+(G41-G$31)^2+(H41-H$31)^2+(I41-I$31)^2+(J41-J$31)^2+(K41-K$31)^2+(L41-L$31)^2) -> 0.36278019 | P41: =MATCH(MIN(M41:O41),M41:O41,0) -> 3 | Q41: =IF(P41=1,"Klaster 1 (Unggulan)",IF(P41=2,"Klaster 2 (Berkembang)","Klaster 3 (Potensial)")) -> Klaster 3 (Potensial)
A42: =A14 -> 4 | B42: =B14 -> Candi Mendut | C42: =C14 -> 0.15002301 | D42: =D14 -> 0.04719284 | E42: =E14 -> 0.079378069 | F42: =F14 -> 0.5 | G42: =G14 -> 0.66666667 | H42: =H14 -> 0.66666667 | ... L42: =L14 -> 0.14324324 | M42: =SQRT((C42-C$29)^2+(D42-D$29)^2+(E42-E$29)^2+(F42-F$29)^2+(G42-G$29)^2+(H42-H$29)^2+(I42-I$29)^2+(J42-J$29)^2+(K42-K$29)^2+(L42-L$29)^2) -> 1.5312476 | N42: =SQRT((C42-C$30)^2+(D42-D$30)^2+(E42-E$30)^2+(F42-F$30)^2+(G42-G$30)^2+(H42-H$30)^2+(I42-I$30)^2+(J42-J$30)^2+(K42-K$30)^2+(L42-L$30)^2) -> 1.4476874 | O42: =SQRT((C42-C$31)^2+(D42-D$31)^2+(E42-E$31)^2+(F42-F$31)^2+(G42-G$31)^2+(H42-H$31)^2+(I42-I$31)^2+(J42-J$31)^2+(K42-K$31)^2+(L42-L$31)^2) -> 0.34478079 | P42: =MATCH(MIN(M42:O42),M42:O42,0) -> 3 | Q42: =IF(P42=1,"Klaster 1 (Unggulan)",IF(P42=2,"Klaster 2 (Berkembang)","Klaster 3 (Potensial)")) -> Klaster 3 (Potensial)
A43: =A15 -> 5 | B43: =B15 -> Ketep Pass | C43: =C15 -> 0.28163829 | D43: =D15 -> 0.10781123 | E43: =E15 -> 0.14893617 | F43: =F15 -> 0.66666667 | G43: =G15 -> 0.33333333 | H43: =H15 -> 0.66666667 | ... L43: =L15 -> 0.31081081 | M43: =SQRT((C43-C$29)^2+(D43-D$29)^2+(E43-E$29)^2+(F43-F$29)^2+(G43-G$29)^2+(H43-H$29)^2+(I43-I$29)^2+(J43-J$29)^2+(K43-K$29)^2+(L43-L$29)^2) -> 1.6527701 | N43: =SQRT((C43-C$30)^2+(D43-D$30)^2+(E43-E$30)^2+(F43-F$30)^2+(G43-G$30)^2+(H43-H$30)^2+(I43-I$30)^2+(J43-J$30)^2+(K43-K$30)^2+(L43-L$30)^2) -> 0.82773777 | O43: =SQRT((C43-C$31)^2+(D43-D$31)^2+(E43-E$31)^2+(F43-F$31)^2+(G43-G$31)^2+(H43-H$31)^2+(I43-I$31)^2+(J43-J$31)^2+(K43-K$31)^2+(L43-L$31)^2) -> 0.84566052 | P43: =MATCH(MIN(M43:O43),M43:O43,0) -> 2 | Q43: =IF(P43=1,"Klaster 1 (Unggulan)",IF(P43=2,"Klaster 2 (Berkembang)","Klaster 3 (Potensial)")) -> Klaster 2 (Berkembang)
A44: =A16 -> 6 | B44: =B16 -> Kopeng | C44: =C16 -> 0.94799816 | D44: =D16 -> 0.86533767 | E44: =E16 -> 0.057283142 | F44: =F16 -> 0.083333333 | G44: =G16 -> 0.33333333 | H44: =H16 -> 0.33333333 | ... L44: =L16 -> 0.02972973 | M44: =SQRT((C44-C$29)^2+(D44-D$29)^2+(E44-E$29)^2+(F44-F$29)^2+(G44-G$29)^2+(H44-H$29)^2+(I44-I$29)^2+(J44-J$29)^2+(K44-K$29)^2+(L44-L$29)^2) -> 2.4787369 | N44: =SQRT((C44-C$30)^2+(D44-D$30)^2+(E44-E$30)^2+(F44-F$30)^2+(G44-G$30)^2+(H44-H$30)^2+(I44-I$30)^2+(J44-J$30)^2+(K44-K$30)^2+(L44-L$30)^2) -> 0.93113714 | O44: =SQRT((C44-C$31)^2+(D44-D$31)^2+(E44-E$31)^2+(F44-F$31)^2+(G44-G$31)^2+(H44-H$31)^2+(I44-I$31)^2+(J44-J$31)^2+(K44-K$31)^2+(L44-L$31)^2) -> 1.5146218 | P44: =MATCH(MIN(M44:O44),M44:O44,0) -> 2 | Q44: =IF(P44=1,"Klaster 1 (Unggulan)",IF(P44=2,"Klaster 2 (Berkembang)","Klaster 3 (Potensial)")) -> Klaster 2 (Berkembang)
A45: =A17 -> 7 | B45: =B17 -> Air Terjun Kedung Kayang | C45: =C17 -> 0.33916245 | D45: =D17 -> 0.16273393 | E45: =E17 -> 0.011456628 | F45: =F17 -> 0.58333333 | G45: =G17 -> 0 | H45: =H17 -> 0 | ... L45: =L17 -> 0.48378378 | M45: =SQRT((C45-C$29)^2+(D45-D$29)^2+(E45-E$29)^2+(F45-F$29)^2+(G45-G$29)^2+(H45-H$29)^2+(I45-I$29)^2+(J45-J$29)^2+(K45-K$29)^2+(L45-L$29)^2) -> 2.3307557 | N45: =SQRT((C45-C$30)^2+(D45-D$30)^2+(E45-E$30)^2+(F45-F$30)^2+(G45-G$30)^2+(H45-H$30)^2+(I45-I$30)^2+(J45-J$30)^2+(K45-K$30)^2+(L45-L$30)^2) -> 0.44809596 | O45: =SQRT((C45-C$31)^2+(D45-D$31)^2+(E45-E$31)^2+(F45-F$31)^2+(G45-G$31)^2+(H45-H$31)^2+(I45-I$31)^2+(J45-J$31)^2+(K45-K$31)^2+(L45-L$31)^2) -> 1.3009662 | P45: =MATCH(MIN(M45:O45),M45:O45,0) -> 2 | Q45: =IF(P45=1,"Klaster 1 (Unggulan)",IF(P45=2,"Klaster 2 (Berkembang)","Klaster 3 (Potensial)")) -> Klaster 2 (Berkembang)
A46: =A18 -> 8 | B46: =B18 -> Telaga Bleder | C46: =C18 -> 0.58122411 | D46: =D18 -> 0.52441009 | E46: =E18 -> 0.0057283142 | F46: =F18 -> 0.16666667 | G46: =G18 -> 0 | H46: =H18 -> 0 | ... L46: =L18 -> 0.20540541 | M46: =SQRT((C46-C$29)^2+(D46-D$29)^2+(E46-E$29)^2+(F46-F$29)^2+(G46-G$29)^2+(H46-H$29)^2+(I46-I$29)^2+(J46-J$29)^2+(K46-K$29)^2+(L46-L$29)^2) -> 2.4961068 | N46: =SQRT((C46-C$30)^2+(D46-D$30)^2+(E46-E$30)^2+(F46-F$30)^2+(G46-G$30)^2+(H46-H$30)^2+(I46-I$30)^2+(J46-J$30)^2+(K46-K$30)^2+(L46-L$30)^2) -> 0.51589915 | O46: =SQRT((C46-C$31)^2+(D46-D$31)^2+(E46-E$31)^2+(F46-F$31)^2+(G46-G$31)^2+(H46-H$31)^2+(I46-I$31)^2+(J46-J$31)^2+(K46-K$31)^2+(L46-L$31)^2) -> 1.3453149 | P46: =MATCH(MIN(M46:O46),M46:O46,0) -> 2 | Q46: =IF(P46=1,"Klaster 1 (Unggulan)",IF(P46=2,"Klaster 2 (Berkembang)","Klaster 3 (Potensial)")) -> Klaster 2 (Berkembang)
A47: =A19 -> 9 | B47: =B19 -> Bukit Rhema (Gereja Ayam) | C47: =C19 -> 0.031753336 | D47: =D19 -> 0.030105777 | E47: =E19 -> 0.11211129 | F47: =F19 -> 0.75 | G47: =G19 -> 0.33333333 | H47: =H19 -> 0.33333333 | ... L47: =L19 -> 0.83783784 | M47: =SQRT((C47-C$29)^2+(D47-D$29)^2+(E47-E$29)^2+(F47-F$29)^2+(G47-G$29)^2+(H47-H$29)^2+(I47-I$29)^2+(J47-J$29)^2+(K47-K$29)^2+(L47-L$29)^2) -> 1.7430569 | N47: =SQRT((C47-C$30)^2+(D47-D$30)^2+(E47-E$30)^2+(F47-F$30)^2+(G47-G$30)^2+(H47-H$30)^2+(I47-I$30)^2+(J47-J$30)^2+(K47-K$30)^2+(L47-L$30)^2) -> 1.0417203 | O47: =SQRT((C47-C$31)^2+(D47-D$31)^2+(E47-E$31)^2+(F47-F$31)^2+(G47-G$31)^2+(H47-H$31)^2+(I47-I$31)^2+(J47-J$31)^2+(K47-K$31)^2+(L47-L$31)^2) -> 0.77581573 | P47: =MATCH(MIN(M47:O47),M47:O47,0) -> 3 | Q47: =IF(P47=1,"Klaster 1 (Unggulan)",IF(P47=2,"Klaster 2 (Berkembang)","Klaster 3 (Potensial)")) -> Klaster 3 (Potensial)
A48: =A20 -> 10 | B48: =B20 -> Sawah Sukomakmur | C48: =C20 -> 0.17579383 | D48: =D20 -> 0.16842962 | E48: =E20 -> 0 | F48: =F20 -> 0.33333333 | G48: =G20 -> 0 | H48: =H20 -> 0 | ... L48: =L20 -> 0.65405405 | M48: =SQRT((C48-C$29)^2+(D48-D$29)^2+(E48-E$29)^2+(F48-F$29)^2+(G48-G$29)^2+(H48-H$29)^2+(I48-I$29)^2+(J48-J$29)^2+(K48-K$29)^2+(L48-L$29)^2) -> 2.2873674 | N48: =SQRT((C48-C$30)^2+(D48-D$30)^2+(E48-E$30)^2+(F48-F$30)^2+(G48-G$30)^2+(H48-H$30)^2+(I48-I$30)^2+(J48-J$30)^2+(K48-K$30)^2+(L48-L$30)^2) -> 0.54919202 | O48: =SQRT((C48-C$31)^2+(D48-D$31)^2+(E48-E$31)^2+(F48-F$31)^2+(G48-G$31)^2+(H48-H$31)^2+(I48-I$31)^2+(J48-J$31)^2+(K48-K$31)^2+(L48-L$31)^2) -> 1.1544964 | P48: =MATCH(MIN(M48:O48),M48:O48,0) -> 2 | Q48: =IF(P48=1,"Klaster 1 (Unggulan)",IF(P48=2,"Klaster 2 (Berkembang)","Klaster 3 (Potensial)")) -> Klaster 2 (Berkembang)
A49: =A21 -> 11 | B49: =B21 -> Museum Karmawibhangga | C49: =C21 -> 0.040036815 | D49: =D21 -> 0.012205045 | E49: =E21 -> 0.048281506 | F49: =F21 -> 0.25 | G49: =G21 -> 1 | H49: =H21 -> 0.66666667 | ... L49: =L21 -> 0.051351351 | M49: =SQRT((C49-C$29)^2+(D49-D$29)^2+(E49-E$29)^2+(F49-F$29)^2+(G49-G$29)^2+(H49-H$29)^2+(I49-I$29)^2+(J49-J$29)^2+(K49-K$29)^2+(L49-L$29)^2) -> 1.7333118 | N49: =SQRT((C49-C$30)^2+(D49-D$30)^2+(E49-E$30)^2+(F49-F$30)^2+(G49-G$30)^2+(H49-H$30)^2+(I49-I$30)^2+(J49-J$30)^2+(K49-K$30)^2+(L49-L$30)^2) -> 1.8205851 | O49: =SQRT((C49-C$31)^2+(D49-D$31)^2+(E49-E$31)^2+(F49-F$31)^2+(G49-G$31)^2+(H49-H$31)^2+(I49-I$31)^2+(J49-J$31)^2+(K49-K$31)^2+(L49-L$31)^2) -> 0.72517484 | P49: =MATCH(MIN(M49:O49),M49:O49,0) -> 3 | Q49: =IF(P49=1,"Klaster 1 (Unggulan)",IF(P49=2,"Klaster 2 (Berkembang)","Klaster 3 (Potensial)")) -> Klaster 3 (Potensial)
...

Sheet 5_Konvergensi
A1: ANALISIS KONVERGENSI: PERGESERAN CENTROID PER ITERASI
A2: Konvergensi tercapai ketika pergeseran centroid < threshold (ε = 0.0001) atau jumlah iterasi maksimum tercapai
A4: Iterasi | B4: WCSS | C4: ΔC1 (shift) | D4: ΔC2 (shift) | E4: ΔC3 (shift) | F4: Δ Total Shift | G4: Status | H4: Klaster-1 (n) | I4: Klaster-2 (n) | J4: Klaster-3 (n)
A5: 0 | G5: Inisialisasi
A6: 1 | B6: ='4_Iterasi_KMeans++'!C33 -> 14.056938 | C6: 0 | D6: 0.702 | E6: 0.7252 | F6: =SQRT(C6^2+D6^2+E6^2) -> 1.0093161 | G6: Belum Konvergen | H6: =COUNTIF('4_Iterasi_KMeans++'!P11:P25,1) -> 1 | I6: =COUNTIF('4_Iterasi_KMeans++'!P11:P25,2) -> 8 | J6: =COUNTIF('4_Iterasi_KMeans++'!P11:P25,3) -> 6
A7: 2 | B7: ='4_Iterasi_KMeans++'!C61 -> 6.9596061 | C7: 0 | D7: 0 | E7: 0 | F7: =SQRT(C7^2+D7^2+E7^2) -> 0 | G7: ✓ KONVERGEN
A12: Threshold ε | B12: 0.0001

Sheet 6_Hasil_Klaster
A1: HASIL KLASTERISASI FINAL K-MEANS++ – KABUPATEN MAGELANG
A2: ID | B2: Nama Destinasi | C2: Klaster | D2: Label Klaster | E2: Kunjungan/Tahun | F2: Rating | G2: d(x,centroid) | H2: Skor Potensi | I2: Rekomendasi
A3: ='1_Dataset'!A4 -> 1 | B3: ='1_Dataset'!B4 -> Candi Borobudur | C3: ='4_Iterasi_KMeans++'!P11 -> 1 | D3: =IF(C3=1,"Klaster 1: Unggulan",IF(C3=2,"Klaster 2: Berkembang","Klaster 3: Potensial")) -> Klaster 1: Unggulan | E3: ='1_Dataset'!E4 -> 1250000 | F3: ='1_Dataset'!F4 -> 4.9 | G3: =IF(C3=1,'4_Iterasi_KMeans++'!M11,IF(C3=2,'4_Iterasi_KMeans++'!N11,'4_Iterasi_KMeans++'!O11)) -> 0 | H3: =('1_Dataset'!F4/5*0.25+'1_Dataset'!G4/5*0.15+'1_Dataset'!H4/5*0.1+'1_Dataset'!I4/5*0.2+'1_Dataset'!J4/5*0.15+MIN('1_Dataset'!K4,20000)/20000*0.15) -> 0.94375 | I3: =IF(C3=1,"Prioritas pengembangan infrastruktur & promosi",IF(C3=2,"Tingkatkan fasilitas & aksesibilitas","Eksplorasi & pengembangan awal")) -> Prioritas pengembangan infrastruktur & promosi
A4: ='1_Dataset'!A5 -> 2 | B4: ='1_Dataset'!B5 -> Punthuk Setumbu | C4: ='4_Iterasi_KMeans++'!P12 -> 3 | D4: =IF(C4=1,"Klaster 1: Unggulan",IF(C4=2,"Klaster 2: Berkembang","Klaster 3: Potensial")) -> Klaster 3: Potensial | E4: ='1_Dataset'!E5 -> 185000 | F4: ='1_Dataset'!F5 -> 4.7 | G4: =IF(C4=1,'4_Iterasi_KMeans++'!M12,IF(C4=2,'4_Iterasi_KMeans++'!N12,'4_Iterasi_KMeans++'!O12)) -> 1.4634378 | H4: =('1_Dataset'!F5/5*0.25+'1_Dataset'!G5/5*0.15+'1_Dataset'!H5/5*0.1+'1_Dataset'!I5/5*0.2+'1_Dataset'!J5/5*0.15+MIN('1_Dataset'!K5,20000)/20000*0.15) -> 0.726 | I4: =IF(C4=1,"Prioritas pengembangan infrastruktur & promosi",IF(C4=2,"Tingkatkan fasilitas & aksesibilitas","Eksplorasi & pengembangan awal")) -> Eksplorasi & pengembangan awal
A5: ='1_Dataset'!A6 -> 3 | B5: ='1_Dataset'!B6 -> Candi Pawon | C5: ='4_Iterasi_KMeans++'!P13 -> 3 | D5: =IF(C5=1,"Klaster 1: Unggulan",IF(C5=2,"Klaster 2: Berkembang","Klaster 3: Potensial")) -> Klaster 3: Potensial | E5: ='1_Dataset'!E6 -> 95000 | F5: ='1_Dataset'!F6 -> 4.2 | G5: =IF(C5=1,'4_Iterasi_KMeans++'!M13,IF(C5=2,'4_Iterasi_KMeans++'!N13,'4_Iterasi_KMeans++'!O13)) -> 0.60462082 | H5: =('1_Dataset'!F6/5*0.25+'1_Dataset'!G6/5*0.15+'1_Dataset'!H6/5*0.1+'1_Dataset'!I6/5*0.2+'1_Dataset'!J6/5*0.15+MIN('1_Dataset'!K6,20000)/20000*0.15) -> 0.666375 | I5: =IF(C5=1,"Prioritas pengembangan infrastruktur & promosi",IF(C5=2,"Tingkatkan fasilitas & aksesibilitas","Eksplorasi & pengembangan awal")) -> Eksplorasi & pengembangan awal
A6: ='1_Dataset'!A7 -> 4 | B6: ='1_Dataset'!B7 -> Candi Mendut | C6: ='4_Iterasi_KMeans++'!P14 -> 3 | D6: =IF(C6=1,"Klaster 1: Unggulan",IF(C6=2,"Klaster 2: Berkembang","Klaster 3: Potensial")) -> Klaster 3: Potensial | E6: ='1_Dataset'!E7 -> 125000 | F6: ='1_Dataset'!F7 -> 4.3 | G6: =IF(C6=1,'4_Iterasi_KMeans++'!M14,IF(C6=2,'4_Iterasi_KMeans++'!N14,'4_Iterasi_KMeans++'!O14)) -> 0.55530056 | H6: =('1_Dataset'!F7/5*0.25+'1_Dataset'!G7/5*0.15+'1_Dataset'!H7/5*0.1+'1_Dataset'!I7/5*0.2+'1_Dataset'!J7/5*0.15+MIN('1_Dataset'!K7,20000)/20000*0.15) -> 0.694 | I6: =IF(C6=1,"Prioritas pengembangan infrastruktur & promosi",IF(C6=2,"Tingkatkan fasilitas & aksesibilitas","Eksplorasi & pengembangan awal")) -> Eksplorasi & pengembangan awal
A7: ='1_Dataset'!A8 -> 5 | B7: ='1_Dataset'!B8 -> Ketep Pass | C7: ='4_Iterasi_KMeans++'!P15 -> 2 | D7: =IF(C7=1,"Klaster 1: Unggulan",IF(C7=2,"Klaster 2: Berkembang","Klaster 3: Potensial")) -> Klaster 2: Berkembang | E7: ='1_Dataset'!E8 -> 210000 | F7: ='1_Dataset'!F8 -> 4.5 | G7: =IF(C7=1,'4_Iterasi_KMeans++'!M15,IF(C7=2,'4_Iterasi_KMeans++'!N15,'4_Iterasi_KMeans++'!O15)) -> 1.3955546 | H7: =('1_Dataset'!F8/5*0.25+'1_Dataset'!G8/5*0.15+'1_Dataset'!H8/5*0.1+'1_Dataset'!I8/5*0.2+'1_Dataset'!J8/5*0.15+MIN('1_Dataset'!K8,20000)/20000*0.15) -> 0.70825 | I7: =IF(C7=1,"Prioritas pengembangan infrastruktur & promosi",IF(C7=2,"Tingkatkan fasilitas & aksesibilitas","Eksplorasi & pengembangan awal")) -> Tingkatkan fasilitas & aksesibilitas
